<?xml version="1.1"?>

<robot name="trikey" xmlns:xacro="http://ros.org/wiki/xacro">

<!-- Include Gazebo plugins -->
<xacro:include filename="$(find trikey_description)/urdf/urdf_gazebo/robot.gazebo.xacro" />


  <link name= "base_link">
  </link>

  <link name="body_link">
    <visual>
      <origin xyz="0.00252107 -0.0402364 -0.0133064" rpy="0 -0 0" />
      <geometry>
        <mesh filename="package://trikey_description/meshes/motors_base.STL"/>
      </geometry>
      <material name="motors_base_material">
        <color rgba="0.792157 0.819608 0.933333 1.0"/>
      </material>
    </visual>
    <collision>
      <origin xyz="0.00252107 -0.0402364 -0.0133064" rpy="0 -0 0" />
      <geometry>
        <mesh filename="package://trikey_description/meshes/motors_base.STL"/>
      </geometry>
      <material name="motors_base_material">
        <color rgba="0.792157 0.819608 0.933333 1.0"/>
      </material>
    </collision>
    <inertial>
      <origin xyz="-0.103138 -0.0619127 -0.0492546" rpy="0 0 0"/>
      <mass value="18.8276" />
      <inertia ixx="0.303414" ixy="1.35923e-09"  ixz="-1.15948e-09" iyy="0.303414" iyz="-3.03776e-09" izz="0.562153" />
    </inertial>
  </link>


  <!--  Wheels  -->
  <link name="wheel0">
    <visual>
      <origin xyz="0.0157175 -0.000676884 -0.0110091" rpy="-1.5708 -3.56009e-33 -5.76344e-17" />
      <geometry>
        <mesh filename="package://trikey_description/meshes/wheel.STL"/>
      </geometry>
      <material name="wheel_material">
        <color rgba="0.792157 0.819608 0.933333 1.0"/>
      </material>
    </visual>
    <collision>
      <origin xyz="0.0157175 -0.000676884 -0.0110091" rpy="-1.5708 -3.56009e-33 -5.76344e-17" />
      <geometry>
        <mesh filename="package://trikey_description/meshes/wheel.STL"/>
        </geometry>
      <material name="wheel_material">
      <color rgba="0.792157 0.819608 0.933333 1.0"/>
      </material>
    </collision>
    <inertial>
      <origin xyz="-3.2877e-05 -5.91764e-05 -0.0194228" rpy="0 0 0"/>
      <mass value="2.36069" />
      <inertia ixx="0.00466517" ixy="9.17346e-07"  ixz="2.34275e-06" iyy="0.00466772" iyz="-4.20658e-06" izz="0.00786801" />
    </inertial>
  </link>

  <link name="wheel1">
    <visual>
      <origin xyz="0.0157175 -0.000676884 -0.0110091" rpy="-1.5708 4.8608e-17 1.36846e-47" />
      <geometry>
        <mesh filename="package://trikey_description/meshes/wheel.STL"/>
      </geometry>
      <material name="wheel_material">
        <color rgba="0.792157 0.819608 0.933333 1.0"/>
      </material>
    </visual>
    <collision>
      <origin xyz="0.0157175 -0.000676884 -0.0110091" rpy="-1.5708 4.8608e-17 1.36846e-47" />
      <geometry>
      <mesh filename="package://trikey_description/meshes/wheel.STL"/>
      </geometry>
      <material name="wheel_material">
      <color rgba="0.792157 0.819608 0.933333 1.0"/>
      </material>
    </collision>
    <inertial>
      <origin xyz="-3.2877e-05 -5.91764e-05 -0.0194228" rpy="0 0 0"/>
      <mass value="2.36069" />
      <inertia ixx="0.00466517" ixy="9.17346e-07"  ixz="2.34275e-06" iyy="0.00466772" iyz="-4.20658e-06" izz="0.00786801" />
    </inertial>
  </link>

  <link name="wheel2">
    <visual>
      <origin xyz="0.0157175 -0.000676884 -0.00283407" rpy="-1.5708 -2.51863e-17 3.13582e-17" />
      <geometry>
        <mesh filename="package://trikey_description/meshes/wheel.STL"/>
      </geometry>
      <material name="wheel_material">
        <color rgba="0.792157 0.819608 0.933333 1.0"/>
      </material>
    </visual>
    <collision>
      <origin xyz="0.0157175 -0.000676884 -0.00283407" rpy="-1.5708 -2.51863e-17 3.13582e-17" />
      <geometry>
        <mesh filename="package://trikey_description/meshes/wheel.STL"/>
      </geometry>
      <material name="wheel_material">
        <color rgba="0.792157 0.819608 0.933333 1.0"/>
      </material>
    </collision>
    <inertial>
      <origin xyz="-3.2877e-05 -5.91764e-05 -0.0112478" rpy="0 0 0"/>
      <mass value="2.36069" />
      <inertia ixx="0.00466517" ixy="9.17346e-07"  ixz="2.34275e-06" iyy="0.00466772" iyz="-4.20658e-06" izz="0.00786801" />
    </inertial>
  </link>

  <link name="lidar_link">
    <visual>
      <origin xyz="0 0 0" rpy="1.57079632679 0 0"/>
      <geometry>
        <mesh filename="package://trikey_description/meshes/rplidar.dae" scale="0.001 0.001 0.001"/>
      </geometry>
      <material name="lidar_material">
        <color rgba="0.8 0.8 0.8 1.0"/>
      </material>
    </visual>
    <collision>
      <origin xyz="0.0 0.0 0.0"/>
      <geometry>
        <mesh filename="package://trikey_description/meshes/rplidar.dae" scale="0.001 0.001 0.001"/>
      </geometry>
      <material name="lidar_material">
        <color rgba="0.8 0.8 0.8 1.0"/>
      </material>
    </collision>
    <inertial>
      <origin xyz="0 0 0" rpy="1.57079632679 0 0"/>
      <mass value="1e-6" />
      <inertia ixx="1e-6" ixy="1e-6"  ixz="1e-6" iyy="1e-6" iyz="1e-6" izz="1e-6" />
    </inertial>
  </link>


  <!-- Azure Kinect Camera Link (Top Camera) -->
  <link name="camera_link">
    <visual>
      <origin xyz="0 0 0" rpy="0 0 0"/>
      <geometry>
        <mesh filename="package://trikey_description/meshes/Azure_Kinect.stl"/>
      </geometry>
      <material name="kinect_material">
        <color rgba="0.9 0.2 0.24 1.0"/>
      </material>
    </visual>

    <collision>
      <origin xyz="0.0 0.0 0.0"/>
      <geometry>
        <mesh filename="package://trikey_description/meshes/Azure_Kinect.stl"/>
      </geometry>
      <material name="kinect_material">
        <color rgba="0.9 0.2 0.24 1.0"/>
      </material>
    </collision>
    
    <inertial>
      <origin xyz="0 0 0" rpy="0 0 0"/>
      <mass value=".44" />
      <inertia ixx="10.173985" ixy="0.212137"  ixz="-0.09591" iyy="5.191632" iyz="0.505713" izz="5.853716" />
    </inertial>
  </link>


  <!-- Azure Kinect Camera Lense Link (Top Camera) -->
  <link name="kinect_1_lense_link">
    <visual>
      <origin xyz="0 0 0" rpy="0 1.57 0" />
      <geometry>
        <cylinder length="0.001" radius="0.01"/>
      </geometry>
    </visual>
  </link>




  <!-- Joints -->

  <joint name="body_joint" type="fixed">
    <origin xyz="-0.06 0.1 0" rpy="0 0 1.57"/>
    <parent link="base_link"/>
    <child link="body_link"/>
  </joint>

  <joint name="wheel0_joint" type="continuous">
    <origin xyz="-0.103157 -0.317313 -0.144393" rpy="1.5708 0.599769 -5.54919e-17" />
    <parent link="body_link" />
    <child link="wheel0" />
    <axis xyz="0 0 1"/>
    <limit effort="2" velocity="20" />
    <joint_properties friction="0.0"/>
  </joint>

  <joint name="wheel1_joint" type="continuous">
    <origin xyz="0.110261 0.0612702 -0.144393" rpy="1.5708 0.632117 2.0944" />
    <parent link="body_link" />
    <child link="wheel1" />
    <axis xyz="0 0 1"/>
    <limit effort="2" velocity="20" />
    <joint_properties friction="0.0"/>
  </joint>

  <joint name="wheel2_joint" type="continuous">
    <origin xyz="-0.323445 0.0653045 -0.144393" rpy="-1.5708 -1.38778e-17 1.0472" />
    <parent link="body_link" />
    <child link="wheel2" />
    <axis xyz="0 0 1"/>
    <limit effort="2" velocity="20" />
    <joint_properties friction="0.0"/>
  </joint>

  <!-- Distance from chassis center to lidar are (from CAD): [0 -0.232682 0.34108] -->
  <!-- distance from chassis STL origin to actual center (manually tuned): [-0.103 -0.057 0] -->
  <joint name="lidar_joint" type="fixed">
    <origin xyz="-0.103 -0.289682 0.34108" rpy="0. 0. 1.57079632"/>
    <parent link="body_link"/>
    <child link="lidar_link"/>
  </joint>


    <!-- Kinect Camera Joints -->
    <joint name="kinect_1_joint" type="fixed">
        <origin xyz="-0.1144 -0.261352 0.22108" rpy="0 -1.57079632679 1.57079632679"/>
        <parent link="body_link"/>
        <child link="camera_link"/>
    </joint>


    <joint name="kinect_1_lense_joint" type="fixed">
        <origin xyz="-0.03 0 0.01" rpy="3.14 -1.57 0"/>
        <parent link="camera_link"/>
        <child link="kinect_1_lense_link"/>
    </joint>


</robot>
