<?xml version="1.1"?>
<robot name="trikey" xmlns:xacro="http://ros.org/wiki/xacro">


<link name="base_link">
<visual>
<origin xyz="0.007652 0.00490494 0.000231732" rpy="-1.11735e-06 1.93532e-06 2.69365e-06" />
<geometry>
<mesh filename="package://trikey_description/urdf/urdf_generator/motors_base.stl"/>
</geometry>
<material name="motors_base_material">
<color rgba="0.792157 0.819608 0.933333 1.0"/>
</material>
</visual>
<collision>
<origin xyz="0.007652 0.00490494 0.000231732" rpy="-1.11735e-06 1.93532e-06 2.69365e-06" />
<geometry>
<mesh filename="package://trikey_description/urdf/urdf_generator/motors_base.stl"/>
</geometry>
<material name="motors_base_material">
<color rgba="0.792157 0.819608 0.933333 1.0"/>
</material>
</collision>
<inertial>
<origin xyz="0.00765321 0.00490866 -0.0357164" rpy="0 0 0"/>
<mass value="18.8276" />
<inertia ixx="0.303414" ixy="1.3598e-09"  ixz="-5.01901e-07" iyy="0.303414" iyz="-2.9214e-07" izz="0.562153" />
</inertial>
</link>

<link name="wheel">
<visual>
<origin xyz="0.0157175 -0.000676884 -0.00283407" rpy="-1.5708 1.4944e-22 -1.48983e-28" />
<geometry>
<mesh filename="package://trikey_description/urdf/urdf_generator/wheel.stl"/>
</geometry>
<material name="wheel_material">
<color rgba="0.792157 0.819608 0.933333 1.0"/>
</material>
</visual>
<collision>
<origin xyz="0.0157175 -0.000676884 -0.00283407" rpy="-1.5708 1.4944e-22 -1.48983e-28" />
<geometry>
<mesh filename="package://trikey_description/urdf/urdf_generator/wheel.stl"/>
</geometry>
<material name="wheel_material">
<color rgba="0.792157 0.819608 0.933333 1.0"/>
</material>
</collision>
<inertial>
<origin xyz="-3.2877e-05 -5.91764e-05 -0.0112478" rpy="0 0 0"/>
<mass value="2.36069" />
<inertia ixx="0.00466517" ixy="9.17346e-07"  ixz="2.34275e-06" iyy="0.00466772" iyz="-4.20658e-06" izz="0.00786801" />
</inertial>
</link>

<link name="8x750roller">
<visual>
<origin xyz="2.77556e-17 0 -0.0076581" rpy="-1.5708 -1.5708 0" />
<geometry>
<mesh filename="package://trikey_description/urdf/urdf_generator/8x750roller.stl"/>
</geometry>
<material name="8x750roller_material">
<color rgba="0.792157 0.819608 0.933333 1.0"/>
</material>
</visual>
<collision>
<origin xyz="2.77556e-17 0 -0.0076581" rpy="-1.5708 -1.5708 0" />
<geometry>
<mesh filename="package://trikey_description/urdf/urdf_generator/8x750roller.stl"/>
</geometry>
<material name="8x750roller_material">
<color rgba="0.792157 0.819608 0.933333 1.0"/>
</material>
</collision>
<inertial>
<origin xyz="0 0 0" rpy="0 0 0"/>
<mass value="0.005"/>
<inertia ixx="0.002" ixy="0"  ixz="0" iyy="0.003" iyz="0" izz="0.003" />
</inertial>
</link>

<joint name="roller_w0_0" type="continuous">
<origin xyz="0.0835653 -0.0394107 0.0065875" rpy="-1.5708 1.57079 -0.523599" />
<parent link="wheel" />
<child link="8x750roller" />
<axis xyz="0 0 1"/>
<limit effort="100" velocity="20" />
<joint_properties friction="0.0"/>
</joint>

<link name="8x750roller_2">
<visual>
<origin xyz="2.77556e-17 0 -0.00924552" rpy="-1.5708 -1.5708 0" />
<geometry>
<mesh filename="package://trikey_description/urdf/urdf_generator/8x750roller.stl"/>
</geometry>
<material name="8x750roller_material">
<color rgba="0.792157 0.819608 0.933333 1.0"/>
</material>
</visual>
<collision>
<origin xyz="2.77556e-17 0 -0.00924552" rpy="-1.5708 -1.5708 0" />
<geometry>
<mesh filename="package://trikey_description/urdf/urdf_generator/8x750roller.stl"/>
</geometry>
<material name="8x750roller_material">
<color rgba="0.792157 0.819608 0.933333 1.0"/>
</material>
</collision>
<inertial>
<origin xyz="0 0 0" rpy="0 0 0"/>
<mass value="0.005"/>
<inertia ixx="0.002" ixy="0"  ixz="0" iyy="0.003" iyz="0" izz="0.003" />
</inertial>
</link>

<joint name="roller_w0_1" type="continuous">
<origin xyz="0.0665785 -0.0643294 0.0065875" rpy="-0.698132 1.5708 0" />
<parent link="wheel" />
<child link="8x750roller_2" />
<axis xyz="0 0 1"/>
<limit effort="100" velocity="20" />
<joint_properties friction="0.0"/>
</joint>

<link name="8x750roller_3">
<visual>
<origin xyz="-8.72708e-09 -2.00071e-09 -0.00924558" rpy="-1.5708 -1.5708 0" />
<geometry>
<mesh filename="package://trikey_description/urdf/urdf_generator/8x750roller.stl"/>
</geometry>
<material name="8x750roller_material">
<color rgba="0.792157 0.819608 0.933333 1.0"/>
</material>
</visual>
<collision>
<origin xyz="-8.72708e-09 -2.00071e-09 -0.00924558" rpy="-1.5708 -1.5708 0" />
<geometry>
<mesh filename="package://trikey_description/urdf/urdf_generator/8x750roller.stl"/>
</geometry>
<material name="8x750roller_material">
<color rgba="0.792157 0.819608 0.933333 1.0"/>
</material>
</collision>
<inertial>
<origin xyz="0 0 0" rpy="0 0 0"/>
<mass value="0.005"/>
<inertia ixx="0.002" ixy="0"  ixz="0" iyy="0.003" iyz="0" izz="0.003" />
</inertial>
</link>

<joint name="roller_w0_2" type="continuous">
<origin xyz="0.0405614 -0.083221 0.0065875" rpy="-0.349066 1.5708 0" />
<parent link="wheel" />
<child link="8x750roller_3" />
<axis xyz="0 0 1"/>
<limit effort="100" velocity="20" />
<joint_properties friction="0.0"/>
</joint>

<link name="8x750roller_4">
<visual>
<origin xyz="-8.72708e-09 -2.00071e-09 -0.00924558" rpy="-1.5708 -1.5708 0" />
<geometry>
<mesh filename="package://trikey_description/urdf/urdf_generator/8x750roller.stl"/>
</geometry>
<material name="8x750roller_material">
<color rgba="0.792157 0.819608 0.933333 1.0"/>
</material>
</visual>
<collision>
<origin xyz="-8.72708e-09 -2.00071e-09 -0.00924558" rpy="-1.5708 -1.5708 0" />
<geometry>
<mesh filename="package://trikey_description/urdf/urdf_generator/8x750roller.stl"/>
</geometry>
<material name="8x750roller_material">
<color rgba="0.792157 0.819608 0.933333 1.0"/>
</material>
</collision>
<inertial>
<origin xyz="0 0 0" rpy="0 0 0"/>
<mass value="0.005"/>
<inertia ixx="0.002" ixy="0"  ixz="0" iyy="0.003" iyz="0" izz="0.003" />
</inertial>
</link>

<joint name="roller_w0_3" type="continuous">
<origin xyz="0.009652 -0.092075 0.0065875" rpy="1.5708 1.5708 1.5708" />
<parent link="wheel" />
<child link="8x750roller_4" />
<axis xyz="0 0 1"/>
<limit effort="100" velocity="20" />
<joint_properties friction="0.0"/>
</joint>

<link name="8x750roller_5">
<visual>
<origin xyz="-8.72708e-09 -2.00071e-09 -0.00924558" rpy="-1.5708 -1.5708 0" />
<geometry>
<mesh filename="package://trikey_description/urdf/urdf_generator/8x750roller.stl"/>
</geometry>
<material name="8x750roller_material">
<color rgba="0.792157 0.819608 0.933333 1.0"/>
</material>
</visual>
<collision>
<origin xyz="-8.72708e-09 -2.00071e-09 -0.00924558" rpy="-1.5708 -1.5708 0" />
<geometry>
<mesh filename="package://trikey_description/urdf/urdf_generator/8x750roller.stl"/>
</geometry>
<material name="8x750roller_material">
<color rgba="0.792157 0.819608 0.933333 1.0"/>
</material>
</collision>
<inertial>
<origin xyz="0 0 0" rpy="0 0 0"/>
<mass value="0.005"/>
<inertia ixx="0.002" ixy="0"  ixz="0" iyy="0.003" iyz="0" izz="0.003" />
</inertial>
</link>

<joint name="roller_w0_4" type="continuous">
<origin xyz="-0.0224216 -0.0898234 0.0065875" rpy="1.5708 1.57079 1.22173" />
<parent link="wheel" />
<child link="8x750roller_5" />
<axis xyz="0 0 1"/>
<limit effort="100" velocity="20" />
<joint_properties friction="0.0"/>
</joint>

<link name="8x750roller_6">
<visual>
<origin xyz="-8.72708e-09 -2.00071e-09 -0.00924558" rpy="-1.5708 -1.5708 0" />
<geometry>
<mesh filename="package://trikey_description/urdf/urdf_generator/8x750roller.stl"/>
</geometry>
<material name="8x750roller_material">
<color rgba="0.792157 0.819608 0.933333 1.0"/>
</material>
</visual>
<collision>
<origin xyz="-8.72708e-09 -2.00071e-09 -0.00924558" rpy="-1.5708 -1.5708 0" />
<geometry>
<mesh filename="package://trikey_description/urdf/urdf_generator/8x750roller.stl"/>
</geometry>
<material name="8x750roller_material">
<color rgba="0.792157 0.819608 0.933333 1.0"/>
</material>
</collision>
<inertial>
<origin xyz="0 0 0" rpy="0 0 0"/>
<mass value="0.005"/>
<inertia ixx="0.002" ixy="0"  ixz="0" iyy="0.003" iyz="0" izz="0.003" />
</inertial>
</link>

<joint name="roller_w0_5" type="continuous">
<origin xyz="-0.0517908 -0.0767377 0.0065875" rpy="1.5708 1.57079 0.872665" />
<parent link="wheel" />
<child link="8x750roller_6" />
<axis xyz="0 0 1"/>
<limit effort="100" velocity="20" />
<joint_properties friction="0.0"/>
</joint>

<link name="8x750roller_7">
<visual>
<origin xyz="8.72708e-09 2.00071e-09 -0.00924558" rpy="1.5708 1.5708 0" />
<geometry>
<mesh filename="package://trikey_description/urdf/urdf_generator/8x750roller.stl"/>
</geometry>
<material name="8x750roller_material">
<color rgba="0.792157 0.819608 0.933333 1.0"/>
</material>
</visual>
<collision>
<origin xyz="8.72708e-09 2.00071e-09 -0.00924558" rpy="1.5708 1.5708 0" />
<geometry>
<mesh filename="package://trikey_description/urdf/urdf_generator/8x750roller.stl"/>
</geometry>
<material name="8x750roller_material">
<color rgba="0.792157 0.819608 0.933333 1.0"/>
</material>
</collision>
<inertial>
<origin xyz="0 0 0" rpy="0 0 0"/>
<mass value="0.005"/>
<inertia ixx="0.002" ixy="0"  ixz="0" iyy="0.003" iyz="0" izz="0.003" />
</inertial>
</link>

<joint name="roller_w0_6" type="continuous">
<origin xyz="-0.0749133 -0.0543964 0.0065875" rpy="1.5708 1.57079 0.523599" />
<parent link="wheel" />
<child link="8x750roller_7" />
<axis xyz="0 0 1"/>
<limit effort="100" velocity="20" />
<joint_properties friction="0.0"/>
</joint>

<link name="8x750roller_8">
<visual>
<origin xyz="8.72708e-09 2.00071e-09 -0.00924558" rpy="1.5708 1.5708 0" />
<geometry>
<mesh filename="package://trikey_description/urdf/urdf_generator/8x750roller.stl"/>
</geometry>
<material name="8x750roller_material">
<color rgba="0.792157 0.819608 0.933333 1.0"/>
</material>
</visual>
<collision>
<origin xyz="8.72708e-09 2.00071e-09 -0.00924558" rpy="1.5708 1.5708 0" />
<geometry>
<mesh filename="package://trikey_description/urdf/urdf_generator/8x750roller.stl"/>
</geometry>
<material name="8x750roller_material">
<color rgba="0.792157 0.819608 0.933333 1.0"/>
</material>
</collision>
<inertial>
<origin xyz="0 0 0" rpy="0 0 0"/>
<mass value="0.005"/>
<inertia ixx="0.002" ixy="0"  ixz="0" iyy="0.003" iyz="0" izz="0.003" />
</inertial>
</link>

<joint name="roller_w0_7" type="continuous">
<origin xyz="-0.0890001 -0.025494 0.0065875" rpy="1.5708 1.57079 0.174533" />
<parent link="wheel" />
<child link="8x750roller_8" />
<axis xyz="0 0 1"/>
<limit effort="100" velocity="20" />
<joint_properties friction="0.0"/>
</joint>

<link name="8x750roller_9">
<visual>
<origin xyz="8.72708e-09 2.00071e-09 -0.00924558" rpy="1.5708 1.5708 0" />
<geometry>
<mesh filename="package://trikey_description/urdf/urdf_generator/8x750roller.stl"/>
</geometry>
<material name="8x750roller_material">
<color rgba="0.792157 0.819608 0.933333 1.0"/>
</material>
</visual>
<collision>
<origin xyz="8.72708e-09 2.00071e-09 -0.00924558" rpy="1.5708 1.5708 0" />
<geometry>
<mesh filename="package://trikey_description/urdf/urdf_generator/8x750roller.stl"/>
</geometry>
<material name="8x750roller_material">
<color rgba="0.792157 0.819608 0.933333 1.0"/>
</material>
</collision>
<inertial>
<origin xyz="0 0 0" rpy="0 0 0"/>
<mass value="0.005"/>
<inertia ixx="0.002" ixy="0"  ixz="0" iyy="0.003" iyz="0" izz="0.003" />
</inertial>
</link>

<joint name="roller_w0_8" type="continuous">
<origin xyz="-0.0923522 0.00648329 0.0065875" rpy="1.5708 1.57079 -0.174533" />
<parent link="wheel" />
<child link="8x750roller_9" />
<axis xyz="0 0 1"/>
<limit effort="100" velocity="20" />
<joint_properties friction="0.0"/>
</joint>

<link name="8x750roller_10">
<visual>
<origin xyz="8.72708e-09 2.00071e-09 -0.00924558" rpy="1.5708 1.5708 0" />
<geometry>
<mesh filename="package://trikey_description/urdf/urdf_generator/8x750roller.stl"/>
</geometry>
<material name="8x750roller_material">
<color rgba="0.792157 0.819608 0.933333 1.0"/>
</material>
</visual>
<collision>
<origin xyz="8.72708e-09 2.00071e-09 -0.00924558" rpy="1.5708 1.5708 0" />
<geometry>
<mesh filename="package://trikey_description/urdf/urdf_generator/8x750roller.stl"/>
</geometry>
<material name="8x750roller_material">
<color rgba="0.792157 0.819608 0.933333 1.0"/>
</material>
</collision>
<inertial>
<origin xyz="0 0 0" rpy="0 0 0"/>
<mass value="0.005"/>
<inertia ixx="0.002" ixy="0"  ixz="0" iyy="0.003" iyz="0" izz="0.003" />
</inertial>
</link>

<joint name="roller_w0_9" type="continuous">
<origin xyz="-0.0845653 0.0376786 0.0065875" rpy="1.5708 1.57079 -0.523599" />
<parent link="wheel" />
<child link="8x750roller_10" />
<axis xyz="0 0 1"/>
<limit effort="100" velocity="20" />
<joint_properties friction="0.0"/>
</joint>

<link name="8x750roller_11">
<visual>
<origin xyz="8.72708e-09 2.00071e-09 -0.00924558" rpy="1.5708 1.5708 0" />
<geometry>
<mesh filename="package://trikey_description/urdf/urdf_generator/8x750roller.stl"/>
</geometry>
<material name="8x750roller_material">
<color rgba="0.792157 0.819608 0.933333 1.0"/>
</material>
</visual>
<collision>
<origin xyz="8.72708e-09 2.00071e-09 -0.00924558" rpy="1.5708 1.5708 0" />
<geometry>
<mesh filename="package://trikey_description/urdf/urdf_generator/8x750roller.stl"/>
</geometry>
<material name="8x750roller_material">
<color rgba="0.792157 0.819608 0.933333 1.0"/>
</material>
</collision>
<inertial>
<origin xyz="0 0 0" rpy="0 0 0"/>
<mass value="0.005"/>
<inertia ixx="0.002" ixy="0"  ixz="0" iyy="0.003" iyz="0" izz="0.003" />
</inertial>
</link>

<joint name="roller_w0_10" type="continuous">
<origin xyz="-0.0665785 0.0643294 0.0065875" rpy="2.44346 1.5708 0" />
<parent link="wheel" />
<child link="8x750roller_11" />
<axis xyz="0 0 1"/>
<limit effort="100" velocity="20" />
<joint_properties friction="0.0"/>
</joint>

<link name="8x750roller_12">
<visual>
<origin xyz="-8.72708e-09 -2.00071e-09 -0.00924558" rpy="-1.5708 -1.5708 0" />
<geometry>
<mesh filename="package://trikey_description/urdf/urdf_generator/8x750roller.stl"/>
</geometry>
<material name="8x750roller_material">
<color rgba="0.792157 0.819608 0.933333 1.0"/>
</material>
</visual>
<collision>
<origin xyz="-8.72708e-09 -2.00071e-09 -0.00924558" rpy="-1.5708 -1.5708 0" />
<geometry>
<mesh filename="package://trikey_description/urdf/urdf_generator/8x750roller.stl"/>
</geometry>
<material name="8x750roller_material">
<color rgba="0.792157 0.819608 0.933333 1.0"/>
</material>
</collision>
<inertial>
<origin xyz="0 0 0" rpy="0 0 0"/>
<mass value="0.005"/>
<inertia ixx="0.002" ixy="0"  ixz="0" iyy="0.003" iyz="0" izz="0.003" />
</inertial>
</link>

<joint name="roller_w0_11" type="continuous">
<origin xyz="-0.0405614 0.083221 0.0065875" rpy="2.79253 1.5708 0" />
<parent link="wheel" />
<child link="8x750roller_12" />
<axis xyz="0 0 1"/>
<limit effort="100" velocity="20" />
<joint_properties friction="0.0"/>
</joint>

<link name="8x750roller_13">
<visual>
<origin xyz="-8.72708e-09 -2.00071e-09 -0.00924558" rpy="-1.5708 -1.5708 0" />
<geometry>
<mesh filename="package://trikey_description/urdf/urdf_generator/8x750roller.stl"/>
</geometry>
<material name="8x750roller_material">
<color rgba="0.792157 0.819608 0.933333 1.0"/>
</material>
</visual>
<collision>
<origin xyz="-8.72708e-09 -2.00071e-09 -0.00924558" rpy="-1.5708 -1.5708 0" />
<geometry>
<mesh filename="package://trikey_description/urdf/urdf_generator/8x750roller.stl"/>
</geometry>
<material name="8x750roller_material">
<color rgba="0.792157 0.819608 0.933333 1.0"/>
</material>
</collision>
<inertial>
<origin xyz="0 0 0" rpy="0 0 0"/>
<mass value="0.005"/>
<inertia ixx="0.002" ixy="0"  ixz="0" iyy="0.003" iyz="0" izz="0.003" />
</inertial>
</link>

<joint name="roller_w0_12" type="continuous">
<origin xyz="-0.009652 0.092075 0.0065875" rpy="-1.5708 1.5708 1.5708" />
<parent link="wheel" />
<child link="8x750roller_13" />
<axis xyz="0 0 1"/>
<limit effort="100" velocity="20" />
<joint_properties friction="0.0"/>
</joint>

<link name="8x750roller_14">
<visual>
<origin xyz="-8.72708e-09 -2.00071e-09 -0.00924558" rpy="-1.5708 -1.5708 0" />
<geometry>
<mesh filename="package://trikey_description/urdf/urdf_generator/8x750roller.stl"/>
</geometry>
<material name="8x750roller_material">
<color rgba="0.792157 0.819608 0.933333 1.0"/>
</material>
</visual>
<collision>
<origin xyz="-8.72708e-09 -2.00071e-09 -0.00924558" rpy="-1.5708 -1.5708 0" />
<geometry>
<mesh filename="package://trikey_description/urdf/urdf_generator/8x750roller.stl"/>
</geometry>
<material name="8x750roller_material">
<color rgba="0.792157 0.819608 0.933333 1.0"/>
</material>
</collision>
<inertial>
<origin xyz="0 0 0" rpy="0 0 0"/>
<mass value="0.005"/>
<inertia ixx="0.002" ixy="0"  ixz="0" iyy="0.003" iyz="0" izz="0.003" />
</inertial>
</link>

<joint name="roller_w0_13" type="continuous">
<origin xyz="0.0224216 0.0898234 0.0065875" rpy="-1.5708 1.57079 1.22173" />
<parent link="wheel" />
<child link="8x750roller_14" />
<axis xyz="0 0 1"/>
<limit effort="100" velocity="20" />
<joint_properties friction="0.0"/>
</joint>

<link name="8x750roller_15">
<visual>
<origin xyz="-8.72708e-09 -2.00071e-09 -0.00924558" rpy="-1.5708 -1.5708 0" />
<geometry>
<mesh filename="package://trikey_description/urdf/urdf_generator/8x750roller.stl"/>
</geometry>
<material name="8x750roller_material">
<color rgba="0.792157 0.819608 0.933333 1.0"/>
</material>
</visual>
<collision>
<origin xyz="-8.72708e-09 -2.00071e-09 -0.00924558" rpy="-1.5708 -1.5708 0" />
<geometry>
<mesh filename="package://trikey_description/urdf/urdf_generator/8x750roller.stl"/>
</geometry>
<material name="8x750roller_material">
<color rgba="0.792157 0.819608 0.933333 1.0"/>
</material>
</collision>
<inertial>
<origin xyz="0 0 0" rpy="0 0 0"/>
<mass value="0.005"/>
<inertia ixx="0.002" ixy="0"  ixz="0" iyy="0.003" iyz="0" izz="0.003" />
</inertial>
</link>

<joint name="roller_w0_14" type="continuous">
<origin xyz="0.0517908 0.0767377 0.0065875" rpy="-1.5708 1.57079 0.872665" />
<parent link="wheel" />
<child link="8x750roller_15" />
<axis xyz="0 0 1"/>
<limit effort="100" velocity="20" />
<joint_properties friction="0.0"/>
</joint>

<link name="8x750roller_16">
<visual>
<origin xyz="-8.72708e-09 -2.00071e-09 -0.00924558" rpy="-1.5708 -1.5708 0" />
<geometry>
<mesh filename="package://trikey_description/urdf/urdf_generator/8x750roller.stl"/>
</geometry>
<material name="8x750roller_material">
<color rgba="0.792157 0.819608 0.933333 1.0"/>
</material>
</visual>
<collision>
<origin xyz="-8.72708e-09 -2.00071e-09 -0.00924558" rpy="-1.5708 -1.5708 0" />
<geometry>
<mesh filename="package://trikey_description/urdf/urdf_generator/8x750roller.stl"/>
</geometry>
<material name="8x750roller_material">
<color rgba="0.792157 0.819608 0.933333 1.0"/>
</material>
</collision>
<inertial>
<origin xyz="0 0 0" rpy="0 0 0"/>
<mass value="0.005"/>
<inertia ixx="0.002" ixy="0"  ixz="0" iyy="0.003" iyz="0" izz="0.003" />
</inertial>
</link>

<joint name="roller_w0_15" type="continuous">
<origin xyz="0.0749133 0.0543964 0.0065875" rpy="-1.5708 1.57079 0.523599" />
<parent link="wheel" />
<child link="8x750roller_16" />
<axis xyz="0 0 1"/>
<limit effort="100" velocity="20" />
<joint_properties friction="0.0"/>
</joint>

<link name="8x750roller_17">
<visual>
<origin xyz="-8.72708e-09 -2.00071e-09 -0.00924558" rpy="-1.5708 -1.5708 0" />
<geometry>
<mesh filename="package://trikey_description/urdf/urdf_generator/8x750roller.stl"/>
</geometry>
<material name="8x750roller_material">
<color rgba="0.792157 0.819608 0.933333 1.0"/>
</material>
</visual>
<collision>
<origin xyz="-8.72708e-09 -2.00071e-09 -0.00924558" rpy="-1.5708 -1.5708 0" />
<geometry>
<mesh filename="package://trikey_description/urdf/urdf_generator/8x750roller.stl"/>
</geometry>
<material name="8x750roller_material">
<color rgba="0.792157 0.819608 0.933333 1.0"/>
</material>
</collision>
<inertial>
<origin xyz="0 0 0" rpy="0 0 0"/>
<mass value="0.005"/>
<inertia ixx="0.002" ixy="0"  ixz="0" iyy="0.003" iyz="0" izz="0.003" />
</inertial>
</link>

<joint name="roller_w0_16" type="continuous">
<origin xyz="0.0890001 0.025494 0.0065875" rpy="-1.5708 1.57079 0.174533" />
<parent link="wheel" />
<child link="8x750roller_17" />
<axis xyz="0 0 1"/>
<limit effort="100" velocity="20" />
<joint_properties friction="0.0"/>
</joint>

<link name="8x750roller_18">
<visual>
<origin xyz="8.72708e-09 2.00071e-09 -0.00924558" rpy="1.5708 1.5708 0" />
<geometry>
<mesh filename="package://trikey_description/urdf/urdf_generator/8x750roller.stl"/>
</geometry>
<material name="8x750roller_material">
<color rgba="0.792157 0.819608 0.933333 1.0"/>
</material>
</visual>
<collision>
<origin xyz="8.72708e-09 2.00071e-09 -0.00924558" rpy="1.5708 1.5708 0" />
<geometry>
<mesh filename="package://trikey_description/urdf/urdf_generator/8x750roller.stl"/>
</geometry>
<material name="8x750roller_material">
<color rgba="0.792157 0.819608 0.933333 1.0"/>
</material>
</collision>
<inertial>
<origin xyz="0 0 0" rpy="0 0 0"/>
<mass value="0.005"/>
<inertia ixx="0.002" ixy="0"  ixz="0" iyy="0.003" iyz="0" izz="0.003" />
</inertial>
</link>

<joint name="roller_w0_17" type="continuous">
<origin xyz="0.0890001 -0.025494 0.0065875" rpy="1.5708 1.57079 -0.174533" />
<parent link="wheel" />
<child link="8x750roller_18" />
<axis xyz="0 0 1"/>
<limit effort="100" velocity="20" />
<joint_properties friction="0.0"/>
</joint>

<joint name="wheel0_joint" type="continuous">
<origin xyz="0.0076339 -0.242491 -0.130854" rpy="1.5708 1.50474e-12 2.69365e-06" />
<parent link="base_link" />
<child link="wheel" />
<axis xyz="0 0 1"/>
<limit effort="30" velocity="20" />
<joint_properties friction="0.0"/>
</joint>

<link name="wheel_2">
<visual>
<origin xyz="0.0157175 -0.000676884 -0.0110091" rpy="-1.5708 -7.59903e-17 5.39519e-23" />
<geometry>
<mesh filename="package://trikey_description/urdf/urdf_generator/wheel.stl"/>
</geometry>
<material name="wheel_material">
<color rgba="0.792157 0.819608 0.933333 1.0"/>
</material>
</visual>
<collision>
<origin xyz="0.0157175 -0.000676884 -0.0110091" rpy="-1.5708 -7.59903e-17 5.39519e-23" />
<geometry>
<mesh filename="package://trikey_description/urdf/urdf_generator/wheel.stl"/>
</geometry>
<material name="wheel_material">
<color rgba="0.792157 0.819608 0.933333 1.0"/>
</material>
</collision>
<inertial>
<origin xyz="-3.2877e-05 -5.91764e-05 -0.0194228" rpy="0 0 0"/>
<mass value="2.36069" />
<inertia ixx="0.00466517" ixy="9.17346e-07"  ixz="2.34275e-06" iyy="0.00466772" iyz="-4.20658e-06" izz="0.00786801" />
</inertial>
</link>

<link name="8x750roller_19">
<visual>
<origin xyz="8.72708e-09 2.00071e-09 -0.00924558" rpy="1.5708 1.5708 0" />
<geometry>
<mesh filename="package://trikey_description/urdf/urdf_generator/8x750roller.stl"/>
</geometry>
<material name="8x750roller_material">
<color rgba="0.792157 0.819608 0.933333 1.0"/>
</material>
</visual>
<collision>
<origin xyz="8.72708e-09 2.00071e-09 -0.00924558" rpy="1.5708 1.5708 0" />
<geometry>
<mesh filename="package://trikey_description/urdf/urdf_generator/8x750roller.stl"/>
</geometry>
<material name="8x750roller_material">
<color rgba="0.792157 0.819608 0.933333 1.0"/>
</material>
</collision>
<inertial>
<origin xyz="0 0 0" rpy="0 0 0"/>
<mass value="0.005"/>
<inertia ixx="0.002" ixy="0"  ixz="0" iyy="0.003" iyz="0" izz="0.003" />
</inertial>
</link>

<joint name="roller_w1_0" type="continuous">
<origin xyz="-0.0749133 0.0543964 -0.0015875" rpy="-1.5708 1.77409e-06 -0.523599" />
<parent link="wheel_2" />
<child link="8x750roller_19" />
<axis xyz="0 0 1"/>
<limit effort="100" velocity="20" />
<joint_properties friction="0.0"/>
</joint>

<link name="8x750roller_20">
<visual>
<origin xyz="-8.72708e-09 -2.00071e-09 -0.00924558" rpy="-1.5708 -1.5708 0" />
<geometry>
<mesh filename="package://trikey_description/urdf/urdf_generator/8x750roller.stl"/>
</geometry>
<material name="8x750roller_material">
<color rgba="0.792157 0.819608 0.933333 1.0"/>
</material>
</visual>
<collision>
<origin xyz="-8.72708e-09 -2.00071e-09 -0.00924558" rpy="-1.5708 -1.5708 0" />
<geometry>
<mesh filename="package://trikey_description/urdf/urdf_generator/8x750roller.stl"/>
</geometry>
<material name="8x750roller_material">
<color rgba="0.792157 0.819608 0.933333 1.0"/>
</material>
</collision>
<inertial>
<origin xyz="0 0 0" rpy="0 0 0"/>
<mass value="0.005"/>
<inertia ixx="0.002" ixy="0"  ixz="0" iyy="0.003" iyz="0" izz="0.003" />
</inertial>
</link>

<joint name="roller_w1_1" type="continuous">
<origin xyz="-0.0665785 0.0643294 -0.0015875" rpy="0.698132 -1.5708 0" />
<parent link="wheel_2" />
<child link="8x750roller_20" />
<axis xyz="0 0 1"/>
<limit effort="100" velocity="20" />
<joint_properties friction="0.0"/>
</joint>

<link name="8x750roller_21">
<visual>
<origin xyz="-8.72708e-09 -2.00071e-09 -0.00924558" rpy="-1.5708 -1.5708 0" />
<geometry>
<mesh filename="package://trikey_description/urdf/urdf_generator/8x750roller.stl"/>
</geometry>
<material name="8x750roller_material">
<color rgba="0.792157 0.819608 0.933333 1.0"/>
</material>
</visual>
<collision>
<origin xyz="-8.72708e-09 -2.00071e-09 -0.00924558" rpy="-1.5708 -1.5708 0" />
<geometry>
<mesh filename="package://trikey_description/urdf/urdf_generator/8x750roller.stl"/>
</geometry>
<material name="8x750roller_material">
<color rgba="0.792157 0.819608 0.933333 1.0"/>
</material>
</collision>
<inertial>
<origin xyz="0 0 0" rpy="0 0 0"/>
<mass value="0.005"/>
<inertia ixx="0.002" ixy="0"  ixz="0" iyy="0.003" iyz="0" izz="0.003" />
</inertial>
</link>

<joint name="roller_w1_2" type="continuous">
<origin xyz="-0.0405614 0.083221 -0.0015875" rpy="0.349066 -1.5708 0" />
<parent link="wheel_2" />
<child link="8x750roller_21" />
<axis xyz="0 0 1"/>
<limit effort="100" velocity="20" />
<joint_properties friction="0.0"/>
</joint>

<link name="8x750roller_22">
<visual>
<origin xyz="-8.72708e-09 -2.00071e-09 -0.00924558" rpy="-1.5708 -1.5708 0" />
<geometry>
<mesh filename="package://trikey_description/urdf/urdf_generator/8x750roller.stl"/>
</geometry>
<material name="8x750roller_material">
<color rgba="0.792157 0.819608 0.933333 1.0"/>
</material>
</visual>
<collision>
<origin xyz="-8.72708e-09 -2.00071e-09 -0.00924558" rpy="-1.5708 -1.5708 0" />
<geometry>
<mesh filename="package://trikey_description/urdf/urdf_generator/8x750roller.stl"/>
</geometry>
<material name="8x750roller_material">
<color rgba="0.792157 0.819608 0.933333 1.0"/>
</material>
</collision>
<inertial>
<origin xyz="0 0 0" rpy="0 0 0"/>
<mass value="0.005"/>
<inertia ixx="0.002" ixy="0"  ixz="0" iyy="0.003" iyz="0" izz="0.003" />
</inertial>
</link>

<joint name="roller_w1_3" type="continuous">
<origin xyz="-0.009652 0.092075 -0.0015875" rpy="-1.5708 -1.5708 1.5708" />
<parent link="wheel_2" />
<child link="8x750roller_22" />
<axis xyz="0 0 1"/>
<limit effort="100" velocity="20" />
<joint_properties friction="0.0"/>
</joint>

<link name="8x750roller_23">
<visual>
<origin xyz="-8.72708e-09 -2.00071e-09 -0.00924558" rpy="-1.5708 -1.5708 0" />
<geometry>
<mesh filename="package://trikey_description/urdf/urdf_generator/8x750roller.stl"/>
</geometry>
<material name="8x750roller_material">
<color rgba="0.792157 0.819608 0.933333 1.0"/>
</material>
</visual>
<collision>
<origin xyz="-8.72708e-09 -2.00071e-09 -0.00924558" rpy="-1.5708 -1.5708 0" />
<geometry>
<mesh filename="package://trikey_description/urdf/urdf_generator/8x750roller.stl"/>
</geometry>
<material name="8x750roller_material">
<color rgba="0.792157 0.819608 0.933333 1.0"/>
</material>
</collision>
<inertial>
<origin xyz="0 0 0" rpy="0 0 0"/>
<mass value="0.005"/>
<inertia ixx="0.002" ixy="0"  ixz="0" iyy="0.003" iyz="0" izz="0.003" />
</inertial>
</link>

<joint name="roller_w1_4" type="continuous">
<origin xyz="0.0224216 0.0898234 -0.0015875" rpy="-1.5708 -1.57079 1.22173" />
<parent link="wheel_2" />
<child link="8x750roller_23" />
<axis xyz="0 0 1"/>
<limit effort="100" velocity="20" />
<joint_properties friction="0.0"/>
</joint>

<link name="8x750roller_24">
<visual>
<origin xyz="-8.72708e-09 -2.00071e-09 -0.00924558" rpy="-1.5708 -1.5708 0" />
<geometry>
<mesh filename="package://trikey_description/urdf/urdf_generator/8x750roller.stl"/>
</geometry>
<material name="8x750roller_material">
<color rgba="0.792157 0.819608 0.933333 1.0"/>
</material>
</visual>
<collision>
<origin xyz="-8.72708e-09 -2.00071e-09 -0.00924558" rpy="-1.5708 -1.5708 0" />
<geometry>
<mesh filename="package://trikey_description/urdf/urdf_generator/8x750roller.stl"/>
</geometry>
<material name="8x750roller_material">
<color rgba="0.792157 0.819608 0.933333 1.0"/>
</material>
</collision>
<inertial>
<origin xyz="0 0 0" rpy="0 0 0"/>
<mass value="0.005"/>
<inertia ixx="0.002" ixy="0"  ixz="0" iyy="0.003" iyz="0" izz="0.003" />
</inertial>
</link>

<joint name="roller_w1_5" type="continuous">
<origin xyz="0.0517908 0.0767377 -0.0015875" rpy="-1.5708 -1.57079 0.872665" />
<parent link="wheel_2" />
<child link="8x750roller_24" />
<axis xyz="0 0 1"/>
<limit effort="100" velocity="20" />
<joint_properties friction="0.0"/>
</joint>

<link name="8x750roller_25">
<visual>
<origin xyz="-8.72708e-09 -2.00071e-09 -0.00924558" rpy="-1.5708 -1.5708 0" />
<geometry>
<mesh filename="package://trikey_description/urdf/urdf_generator/8x750roller.stl"/>
</geometry>
<material name="8x750roller_material">
<color rgba="0.792157 0.819608 0.933333 1.0"/>
</material>
</visual>
<collision>
<origin xyz="-8.72708e-09 -2.00071e-09 -0.00924558" rpy="-1.5708 -1.5708 0" />
<geometry>
<mesh filename="package://trikey_description/urdf/urdf_generator/8x750roller.stl"/>
</geometry>
<material name="8x750roller_material">
<color rgba="0.792157 0.819608 0.933333 1.0"/>
</material>
</collision>
<inertial>
<origin xyz="0 0 0" rpy="0 0 0"/>
<mass value="0.005"/>
<inertia ixx="0.002" ixy="0"  ixz="0" iyy="0.003" iyz="0" izz="0.003" />
</inertial>
</link>

<joint name="roller_w1_6" type="continuous">
<origin xyz="0.0749133 0.0543964 -0.0015875" rpy="-1.5708 2.89145e-06 0.523599" />
<parent link="wheel_2" />
<child link="8x750roller_25" />
<axis xyz="0 0 1"/>
<limit effort="100" velocity="20" />
<joint_properties friction="0.0"/>
</joint>

<link name="8x750roller_26">
<visual>
<origin xyz="-8.72708e-09 -2.00071e-09 -0.00924558" rpy="-1.5708 -1.5708 0" />
<geometry>
<mesh filename="package://trikey_description/urdf/urdf_generator/8x750roller.stl"/>
</geometry>
<material name="8x750roller_material">
<color rgba="0.792157 0.819608 0.933333 1.0"/>
</material>
</visual>
<collision>
<origin xyz="-8.72708e-09 -2.00071e-09 -0.00924558" rpy="-1.5708 -1.5708 0" />
<geometry>
<mesh filename="package://trikey_description/urdf/urdf_generator/8x750roller.stl"/>
</geometry>
<material name="8x750roller_material">
<color rgba="0.792157 0.819608 0.933333 1.0"/>
</material>
</collision>
<inertial>
<origin xyz="0 0 0" rpy="0 0 0"/>
<mass value="0.005"/>
<inertia ixx="0.002" ixy="0"  ixz="0" iyy="0.003" iyz="0" izz="0.003" />
</inertial>
</link>

<joint name="roller_w1_7" type="continuous">
<origin xyz="0.0890001 0.025494 -0.0015875" rpy="-1.5708 2.84675e-06 0.174533" />
<parent link="wheel_2" />
<child link="8x750roller_26" />
<axis xyz="0 0 1"/>
<limit effort="100" velocity="20" />
<joint_properties friction="0.0"/>
</joint>

<link name="8x750roller_27">
<visual>
<origin xyz="-8.72708e-09 -2.00071e-09 -0.00924558" rpy="-1.5708 -1.5708 0" />
<geometry>
<mesh filename="package://trikey_description/urdf/urdf_generator/8x750roller.stl"/>
</geometry>
<material name="8x750roller_material">
<color rgba="0.792157 0.819608 0.933333 1.0"/>
</material>
</visual>
<collision>
<origin xyz="-8.72708e-09 -2.00071e-09 -0.00924558" rpy="-1.5708 -1.5708 0" />
<geometry>
<mesh filename="package://trikey_description/urdf/urdf_generator/8x750roller.stl"/>
</geometry>
<material name="8x750roller_material">
<color rgba="0.792157 0.819608 0.933333 1.0"/>
</material>
</collision>
<inertial>
<origin xyz="0 0 0" rpy="0 0 0"/>
<mass value="0.005"/>
<inertia ixx="0.002" ixy="0"  ixz="0" iyy="0.003" iyz="0" izz="0.003" />
</inertial>
</link>

<joint name="roller_w1_8" type="continuous">
<origin xyz="0.0923522 -0.00648329 -0.0015875" rpy="-1.5708 2.4587e-06 -0.174533" />
<parent link="wheel_2" />
<child link="8x750roller_27" />
<axis xyz="0 0 1"/>
<limit effort="100" velocity="20" />
<joint_properties friction="0.0"/>
</joint>

<link name="8x750roller_28">
<visual>
<origin xyz="-8.72708e-09 -2.00071e-09 -0.00924558" rpy="-1.5708 -1.5708 0" />
<geometry>
<mesh filename="package://trikey_description/urdf/urdf_generator/8x750roller.stl"/>
</geometry>
<material name="8x750roller_material">
<color rgba="0.792157 0.819608 0.933333 1.0"/>
</material>
</visual>
<collision>
<origin xyz="-8.72708e-09 -2.00071e-09 -0.00924558" rpy="-1.5708 -1.5708 0" />
<geometry>
<mesh filename="package://trikey_description/urdf/urdf_generator/8x750roller.stl"/>
</geometry>
<material name="8x750roller_material">
<color rgba="0.792157 0.819608 0.933333 1.0"/>
</material>
</collision>
<inertial>
<origin xyz="0 0 0" rpy="0 0 0"/>
<mass value="0.005"/>
<inertia ixx="0.002" ixy="0"  ixz="0" iyy="0.003" iyz="0" izz="0.003" />
</inertial>
</link>

<joint name="roller_w1_9" type="continuous">
<origin xyz="0.0845653 -0.0376786 -0.0015875" rpy="-1.5708 1.77409e-06 -0.523599" />
<parent link="wheel_2" />
<child link="8x750roller_28" />
<axis xyz="0 0 1"/>
<limit effort="100" velocity="20" />
<joint_properties friction="0.0"/>
</joint>

<link name="8x750roller_29">
<visual>
<origin xyz="-8.72708e-09 -2.00071e-09 -0.00924558" rpy="-1.5708 -1.5708 0" />
<geometry>
<mesh filename="package://trikey_description/urdf/urdf_generator/8x750roller.stl"/>
</geometry>
<material name="8x750roller_material">
<color rgba="0.792157 0.819608 0.933333 1.0"/>
</material>
</visual>
<collision>
<origin xyz="-8.72708e-09 -2.00071e-09 -0.00924558" rpy="-1.5708 -1.5708 0" />
<geometry>
<mesh filename="package://trikey_description/urdf/urdf_generator/8x750roller.stl"/>
</geometry>
<material name="8x750roller_material">
<color rgba="0.792157 0.819608 0.933333 1.0"/>
</material>
</collision>
<inertial>
<origin xyz="0 0 0" rpy="0 0 0"/>
<mass value="0.005"/>
<inertia ixx="0.002" ixy="0"  ixz="0" iyy="0.003" iyz="0" izz="0.003" />
</inertial>
</link>

<joint name="roller_w1_10" type="continuous">
<origin xyz="0.0665785 -0.0643294 -0.0015875" rpy="-2.44346 -1.5708 0" />
<parent link="wheel_2" />
<child link="8x750roller_29" />
<axis xyz="0 0 1"/>
<limit effort="100" velocity="20" />
<joint_properties friction="0.0"/>
</joint>

<link name="8x750roller_30">
<visual>
<origin xyz="-8.72708e-09 -2.00071e-09 -0.00924558" rpy="-1.5708 -1.5708 0" />
<geometry>
<mesh filename="package://trikey_description/urdf/urdf_generator/8x750roller.stl"/>
</geometry>
<material name="8x750roller_material">
<color rgba="0.792157 0.819608 0.933333 1.0"/>
</material>
</visual>
<collision>
<origin xyz="-8.72708e-09 -2.00071e-09 -0.00924558" rpy="-1.5708 -1.5708 0" />
<geometry>
<mesh filename="package://trikey_description/urdf/urdf_generator/8x750roller.stl"/>
</geometry>
<material name="8x750roller_material">
<color rgba="0.792157 0.819608 0.933333 1.0"/>
</material>
</collision>
<inertial>
<origin xyz="0 0 0" rpy="0 0 0"/>
<mass value="0.005"/>
<inertia ixx="0.002" ixy="0"  ixz="0" iyy="0.003" iyz="0" izz="0.003" />
</inertial>
</link>

<joint name="roller_w1_11" type="continuous">
<origin xyz="0.0405614 -0.083221 -0.0015875" rpy="-2.79253 -1.5708 0" />
<parent link="wheel_2" />
<child link="8x750roller_30" />
<axis xyz="0 0 1"/>
<limit effort="100" velocity="20" />
<joint_properties friction="0.0"/>
</joint>

<link name="8x750roller_31">
<visual>
<origin xyz="-8.72708e-09 -2.00071e-09 -0.00924558" rpy="-1.5708 -1.5708 0" />
<geometry>
<mesh filename="package://trikey_description/urdf/urdf_generator/8x750roller.stl"/>
</geometry>
<material name="8x750roller_material">
<color rgba="0.792157 0.819608 0.933333 1.0"/>
</material>
</visual>
<collision>
<origin xyz="-8.72708e-09 -2.00071e-09 -0.00924558" rpy="-1.5708 -1.5708 0" />
<geometry>
<mesh filename="package://trikey_description/urdf/urdf_generator/8x750roller.stl"/>
</geometry>
<material name="8x750roller_material">
<color rgba="0.792157 0.819608 0.933333 1.0"/>
</material>
</collision>
<inertial>
<origin xyz="0 0 0" rpy="0 0 0"/>
<mass value="0.005"/>
<inertia ixx="0.002" ixy="0"  ixz="0" iyy="0.003" iyz="0" izz="0.003" />
</inertial>
</link>

<joint name="roller_w1_12" type="continuous">
<origin xyz="0.009652 -0.092075 -0.0015875" rpy="1.5708 -1.5708 1.5708" />
<parent link="wheel_2" />
<child link="8x750roller_31" />
<axis xyz="0 0 1"/>
<limit effort="100" velocity="20" />
<joint_properties friction="0.0"/>
</joint>

<link name="8x750roller_32">
<visual>
<origin xyz="-8.72708e-09 -2.00071e-09 -0.00924558" rpy="-1.5708 -1.5708 0" />
<geometry>
<mesh filename="package://trikey_description/urdf/urdf_generator/8x750roller.stl"/>
</geometry>
<material name="8x750roller_material">
<color rgba="0.792157 0.819608 0.933333 1.0"/>
</material>
</visual>
<collision>
<origin xyz="-8.72708e-09 -2.00071e-09 -0.00924558" rpy="-1.5708 -1.5708 0" />
<geometry>
<mesh filename="package://trikey_description/urdf/urdf_generator/8x750roller.stl"/>
</geometry>
<material name="8x750roller_material">
<color rgba="0.792157 0.819608 0.933333 1.0"/>
</material>
</collision>
<inertial>
<origin xyz="0 0 0" rpy="0 0 0"/>
<mass value="0.005"/>
<inertia ixx="0.002" ixy="0"  ixz="0" iyy="0.003" iyz="0" izz="0.003" />
</inertial>
</link>

<joint name="roller_w1_13" type="continuous">
<origin xyz="-0.0224216 -0.0898234 -0.0015875" rpy="1.5708 -1.57079 1.22173" />
<parent link="wheel_2" />
<child link="8x750roller_32" />
<axis xyz="0 0 1"/>
<limit effort="100" velocity="20" />
<joint_properties friction="0.0"/>
</joint>

<link name="8x750roller_33">
<visual>
<origin xyz="8.72708e-09 2.00071e-09 -0.00924558" rpy="1.5708 1.5708 0" />
<geometry>
<mesh filename="package://trikey_description/urdf/urdf_generator/8x750roller.stl"/>
</geometry>
<material name="8x750roller_material">
<color rgba="0.792157 0.819608 0.933333 1.0"/>
</material>
</visual>
<collision>
<origin xyz="8.72708e-09 2.00071e-09 -0.00924558" rpy="1.5708 1.5708 0" />
<geometry>
<mesh filename="package://trikey_description/urdf/urdf_generator/8x750roller.stl"/>
</geometry>
<material name="8x750roller_material">
<color rgba="0.792157 0.819608 0.933333 1.0"/>
</material>
</collision>
<inertial>
<origin xyz="0 0 0" rpy="0 0 0"/>
<mass value="0.005"/>
<inertia ixx="0.002" ixy="0"  ixz="0" iyy="0.003" iyz="0" izz="0.003" />
</inertial>
</link>

<joint name="roller_w1_14" type="continuous">
<origin xyz="-0.0517908 -0.0767377 -0.0015875" rpy="1.5708 -1.57079 0.872665" />
<parent link="wheel_2" />
<child link="8x750roller_33" />
<axis xyz="0 0 1"/>
<limit effort="100" velocity="20" />
<joint_properties friction="0.0"/>
</joint>

<link name="8x750roller_34">
<visual>
<origin xyz="8.72708e-09 2.00071e-09 -0.00924558" rpy="1.5708 1.5708 0" />
<geometry>
<mesh filename="package://trikey_description/urdf/urdf_generator/8x750roller.stl"/>
</geometry>
<material name="8x750roller_material">
<color rgba="0.792157 0.819608 0.933333 1.0"/>
</material>
</visual>
<collision>
<origin xyz="8.72708e-09 2.00071e-09 -0.00924558" rpy="1.5708 1.5708 0" />
<geometry>
<mesh filename="package://trikey_description/urdf/urdf_generator/8x750roller.stl"/>
</geometry>
<material name="8x750roller_material">
<color rgba="0.792157 0.819608 0.933333 1.0"/>
</material>
</collision>
<inertial>
<origin xyz="0 0 0" rpy="0 0 0"/>
<mass value="0.005"/>
<inertia ixx="0.002" ixy="0"  ixz="0" iyy="0.003" iyz="0" izz="0.003" />
</inertial>
</link>

<joint name="roller_w1_15" type="continuous">
<origin xyz="-0.0749133 -0.0543964 -0.0015875" rpy="1.5708 2.89145e-06 0.523599" />
<parent link="wheel_2" />
<child link="8x750roller_34" />
<axis xyz="0 0 1"/>
<limit effort="100" velocity="20" />
<joint_properties friction="0.0"/>
</joint>

<link name="8x750roller_35">
<visual>
<origin xyz="8.72708e-09 2.00071e-09 -0.00924558" rpy="1.5708 1.5708 0" />
<geometry>
<mesh filename="package://trikey_description/urdf/urdf_generator/8x750roller.stl"/>
</geometry>
<material name="8x750roller_material">
<color rgba="0.792157 0.819608 0.933333 1.0"/>
</material>
</visual>
<collision>
<origin xyz="8.72708e-09 2.00071e-09 -0.00924558" rpy="1.5708 1.5708 0" />
<geometry>
<mesh filename="package://trikey_description/urdf/urdf_generator/8x750roller.stl"/>
</geometry>
<material name="8x750roller_material">
<color rgba="0.792157 0.819608 0.933333 1.0"/>
</material>
</collision>
<inertial>
<origin xyz="0 0 0" rpy="0 0 0"/>
<mass value="0.005"/>
<inertia ixx="0.002" ixy="0"  ixz="0" iyy="0.003" iyz="0" izz="0.003" />
</inertial>
</link>

<joint name="roller_w1_16" type="continuous">
<origin xyz="-0.0890001 -0.025494 -0.0015875" rpy="1.5708 2.84675e-06 0.174533" />
<parent link="wheel_2" />
<child link="8x750roller_35" />
<axis xyz="0 0 1"/>
<limit effort="100" velocity="20" />
<joint_properties friction="0.0"/>
</joint>

<link name="8x750roller_36">
<visual>
<origin xyz="8.72708e-09 2.00071e-09 -0.00924558" rpy="1.5708 1.5708 0" />
<geometry>
<mesh filename="package://trikey_description/urdf/urdf_generator/8x750roller.stl"/>
</geometry>
<material name="8x750roller_material">
<color rgba="0.792157 0.819608 0.933333 1.0"/>
</material>
</visual>
<collision>
<origin xyz="8.72708e-09 2.00071e-09 -0.00924558" rpy="1.5708 1.5708 0" />
<geometry>
<mesh filename="package://trikey_description/urdf/urdf_generator/8x750roller.stl"/>
</geometry>
<material name="8x750roller_material">
<color rgba="0.792157 0.819608 0.933333 1.0"/>
</material>
</collision>
<inertial>
<origin xyz="0 0 0" rpy="0 0 0"/>
<mass value="0.005"/>
<inertia ixx="0.002" ixy="0"  ixz="0" iyy="0.003" iyz="0" izz="0.003" />
</inertial>
</link>

<joint name="roller_w1_17" type="continuous">
<origin xyz="-0.0923522 0.00648329 -0.0015875" rpy="1.5708 2.4587e-06 -0.174533" />
<parent link="wheel_2" />
<child link="8x750roller_36" />
<axis xyz="0 0 1"/>
<limit effort="100" velocity="20" />
<joint_properties friction="0.0"/>
</joint>

<joint name="wheel1_joint" type="continuous">
<origin xyz="-0.212654 0.132125 -0.130854" rpy="-1.5708 -1.50485e-12 1.0472" />
<parent link="base_link" />
<child link="wheel_2" />
<axis xyz="0 0 1"/>
<limit effort="30" velocity="20" />
<joint_properties friction="0.0"/>
</joint>

<link name="wheel_3">
<visual>
<origin xyz="0.0157175 -0.000676884 -0.0110091" rpy="-1.5708 1.21101e-16 3.64923e-22" />
<geometry>
<mesh filename="package://trikey_description/urdf/urdf_generator/wheel.stl"/>
</geometry>
<material name="wheel_material">
<color rgba="0.792157 0.819608 0.933333 1.0"/>
</material>
</visual>
<collision>
<origin xyz="0.0157175 -0.000676884 -0.0110091" rpy="-1.5708 1.21101e-16 3.64923e-22" />
<geometry>
<mesh filename="package://trikey_description/urdf/urdf_generator/wheel.stl"/>
</geometry>
<material name="wheel_material">
<color rgba="0.792157 0.819608 0.933333 1.0"/>
</material>
</collision>
<inertial>
<origin xyz="-3.2877e-05 -5.91764e-05 -0.0194228" rpy="0 0 0"/>
<mass value="2.36069" />
<inertia ixx="0.00466517" ixy="9.17346e-07"  ixz="2.34275e-06" iyy="0.00466772" iyz="-4.20658e-06" izz="0.00786801" />
</inertial>
</link>

<link name="8x750roller_37">
<visual>
<origin xyz="-8.72708e-09 -2.00071e-09 -0.00924558" rpy="-1.5708 -1.5708 0" />
<geometry>
<mesh filename="package://trikey_description/urdf/urdf_generator/8x750roller.stl"/>
</geometry>
<material name="8x750roller_material">
<color rgba="0.792157 0.819608 0.933333 1.0"/>
</material>
</visual>
<collision>
<origin xyz="-8.72708e-09 -2.00071e-09 -0.00924558" rpy="-1.5708 -1.5708 0" />
<geometry>
<mesh filename="package://trikey_description/urdf/urdf_generator/8x750roller.stl"/>
</geometry>
<material name="8x750roller_material">
<color rgba="0.792157 0.819608 0.933333 1.0"/>
</material>
</collision>
<inertial>
<origin xyz="0 0 0" rpy="0 0 0"/>
<mass value="0.005"/>
<inertia ixx="0.002" ixy="0"  ixz="0" iyy="0.003" iyz="0" izz="0.003" />
</inertial>
</link>

<joint name="roller_w2_0" type="continuous">
<origin xyz="0.0890001 -0.025494 -0.0015875" rpy="-1.5708 -3.04078e-06 2.96706" />
<parent link="wheel_3" />
<child link="8x750roller_37" />
<axis xyz="0 0 1"/>
<limit effort="100" velocity="20" />
<joint_properties friction="0.0"/>
</joint>

<link name="8x750roller_38">
<visual>
<origin xyz="-8.72708e-09 -2.00071e-09 -0.00924558" rpy="-1.5708 -1.5708 0" />
<geometry>
<mesh filename="package://trikey_description/urdf/urdf_generator/8x750roller.stl"/>
</geometry>
<material name="8x750roller_material">
<color rgba="0.792157 0.819608 0.933333 1.0"/>
</material>
</visual>
<collision>
<origin xyz="-8.72708e-09 -2.00071e-09 -0.00924558" rpy="-1.5708 -1.5708 0" />
<geometry>
<mesh filename="package://trikey_description/urdf/urdf_generator/8x750roller.stl"/>
</geometry>
<material name="8x750roller_material">
<color rgba="0.792157 0.819608 0.933333 1.0"/>
</material>
</collision>
<inertial>
<origin xyz="0 0 0" rpy="0 0 0"/>
<mass value="0.005"/>
<inertia ixx="0.002" ixy="0"  ixz="0" iyy="0.003" iyz="0" izz="0.003" />
</inertial>
</link>

<joint name="roller_w2_1" type="continuous">
<origin xyz="0.0923522 0.00648329 -0.0015875" rpy="-1.5708 1.48959e-08 -2.96706" />
<parent link="wheel_3" />
<child link="8x750roller_38" />
<axis xyz="0 0 1"/>
<limit effort="100" velocity="20" />
<joint_properties friction="0.0"/>
</joint>

<link name="8x750roller_39">
<visual>
<origin xyz="-8.72708e-09 -2.00071e-09 -0.00924558" rpy="-1.5708 -1.5708 0" />
<geometry>
<mesh filename="package://trikey_description/urdf/urdf_generator/8x750roller.stl"/>
</geometry>
<material name="8x750roller_material">
<color rgba="0.792157 0.819608 0.933333 1.0"/>
</material>
</visual>
<collision>
<origin xyz="-8.72708e-09 -2.00071e-09 -0.00924558" rpy="-1.5708 -1.5708 0" />
<geometry>
<mesh filename="package://trikey_description/urdf/urdf_generator/8x750roller.stl"/>
</geometry>
<material name="8x750roller_material">
<color rgba="0.792157 0.819608 0.933333 1.0"/>
</material>
</collision>
<inertial>
<origin xyz="0 0 0" rpy="0 0 0"/>
<mass value="0.005"/>
<inertia ixx="0.002" ixy="0"  ixz="0" iyy="0.003" iyz="0" izz="0.003" />
</inertial>
</link>

<joint name="roller_w2_2" type="continuous">
<origin xyz="0.0845653 0.0376786 -0.0015875" rpy="-1.5708 -7.70262e-17 -2.61799" />
<parent link="wheel_3" />
<child link="8x750roller_39" />
<axis xyz="0 0 1"/>
<limit effort="100" velocity="20" />
<joint_properties friction="0.0"/>
</joint>

<link name="8x750roller_40">
<visual>
<origin xyz="-8.72708e-09 -2.00071e-09 -0.00924558" rpy="-1.5708 -1.5708 0" />
<geometry>
<mesh filename="package://trikey_description/urdf/urdf_generator/8x750roller.stl"/>
</geometry>
<material name="8x750roller_material">
<color rgba="0.792157 0.819608 0.933333 1.0"/>
</material>
</visual>
<collision>
<origin xyz="-8.72708e-09 -2.00071e-09 -0.00924558" rpy="-1.5708 -1.5708 0" />
<geometry>
<mesh filename="package://trikey_description/urdf/urdf_generator/8x750roller.stl"/>
</geometry>
<material name="8x750roller_material">
<color rgba="0.792157 0.819608 0.933333 1.0"/>
</material>
</collision>
<inertial>
<origin xyz="0 0 0" rpy="0 0 0"/>
<mass value="0.005"/>
<inertia ixx="0.002" ixy="0"  ixz="0" iyy="0.003" iyz="0" izz="0.003" />
</inertial>
</link>

<joint name="roller_w2_3" type="continuous">
<origin xyz="0.0665785 0.0643294 -0.0015875" rpy="2.44346 -1.5708 0" />
<parent link="wheel_3" />
<child link="8x750roller_40" />
<axis xyz="0 0 1"/>
<limit effort="100" velocity="20" />
<joint_properties friction="0.0"/>
</joint>

<link name="8x750roller_41">
<visual>
<origin xyz="-8.72708e-09 -2.00071e-09 -0.00924558" rpy="-1.5708 -1.5708 0" />
<geometry>
<mesh filename="package://trikey_description/urdf/urdf_generator/8x750roller.stl"/>
</geometry>
<material name="8x750roller_material">
<color rgba="0.792157 0.819608 0.933333 1.0"/>
</material>
</visual>
<collision>
<origin xyz="-8.72708e-09 -2.00071e-09 -0.00924558" rpy="-1.5708 -1.5708 0" />
<geometry>
<mesh filename="package://trikey_description/urdf/urdf_generator/8x750roller.stl"/>
</geometry>
<material name="8x750roller_material">
<color rgba="0.792157 0.819608 0.933333 1.0"/>
</material>
</collision>
<inertial>
<origin xyz="0 0 0" rpy="0 0 0"/>
<mass value="0.005"/>
<inertia ixx="0.002" ixy="0"  ixz="0" iyy="0.003" iyz="0" izz="0.003" />
</inertial>
</link>

<joint name="roller_w2_4" type="continuous">
<origin xyz="0.0405614 0.083221 -0.0015875" rpy="2.79253 -1.5708 0" />
<parent link="wheel_3" />
<child link="8x750roller_41" />
<axis xyz="0 0 1"/>
<limit effort="100" velocity="20" />
<joint_properties friction="0.0"/>
</joint>

<link name="8x750roller_42">
<visual>
<origin xyz="-8.72708e-09 -2.00071e-09 -0.00924558" rpy="-1.5708 -1.5708 0" />
<geometry>
<mesh filename="package://trikey_description/urdf/urdf_generator/8x750roller.stl"/>
</geometry>
<material name="8x750roller_material">
<color rgba="0.792157 0.819608 0.933333 1.0"/>
</material>
</visual>
<collision>
<origin xyz="-8.72708e-09 -2.00071e-09 -0.00924558" rpy="-1.5708 -1.5708 0" />
<geometry>
<mesh filename="package://trikey_description/urdf/urdf_generator/8x750roller.stl"/>
</geometry>
<material name="8x750roller_material">
<color rgba="0.792157 0.819608 0.933333 1.0"/>
</material>
</collision>
<inertial>
<origin xyz="0 0 0" rpy="0 0 0"/>
<mass value="0.005"/>
<inertia ixx="0.002" ixy="0"  ixz="0" iyy="0.003" iyz="0" izz="0.003" />
</inertial>
</link>

<joint name="roller_w2_5" type="continuous">
<origin xyz="0.009652 0.092075 -0.0015875" rpy="-3.14159 -1.5708 0" />
<parent link="wheel_3" />
<child link="8x750roller_42" />
<axis xyz="0 0 1"/>
<limit effort="100" velocity="20" />
<joint_properties friction="0.0"/>
</joint>

<link name="8x750roller_43">
<visual>
<origin xyz="8.72708e-09 2.00071e-09 -0.00924558" rpy="1.5708 1.5708 0" />
<geometry>
<mesh filename="package://trikey_description/urdf/urdf_generator/8x750roller.stl"/>
</geometry>
<material name="8x750roller_material">
<color rgba="0.792157 0.819608 0.933333 1.0"/>
</material>
</visual>
<collision>
<origin xyz="8.72708e-09 2.00071e-09 -0.00924558" rpy="1.5708 1.5708 0" />
<geometry>
<mesh filename="package://trikey_description/urdf/urdf_generator/8x750roller.stl"/>
</geometry>
<material name="8x750roller_material">
<color rgba="0.792157 0.819608 0.933333 1.0"/>
</material>
</collision>
<inertial>
<origin xyz="0 0 0" rpy="0 0 0"/>
<mass value="0.005"/>
<inertia ixx="0.002" ixy="0"  ixz="0" iyy="0.003" iyz="0" izz="0.003" />
</inertial>
</link>

<joint name="roller_w2_6" type="continuous">
<origin xyz="-0.0224216 0.0898234 -0.0015875" rpy="-2.79253 -1.5708 0" />
<parent link="wheel_3" />
<child link="8x750roller_43" />
<axis xyz="0 0 1"/>
<limit effort="100" velocity="20" />
<joint_properties friction="0.0"/>
</joint>

<link name="8x750roller_44">
<visual>
<origin xyz="8.72708e-09 2.00071e-09 -0.00924558" rpy="1.5708 1.5708 0" />
<geometry>
<mesh filename="package://trikey_description/urdf/urdf_generator/8x750roller.stl"/>
</geometry>
<material name="8x750roller_material">
<color rgba="0.792157 0.819608 0.933333 1.0"/>
</material>
</visual>
<collision>
<origin xyz="8.72708e-09 2.00071e-09 -0.00924558" rpy="1.5708 1.5708 0" />
<geometry>
<mesh filename="package://trikey_description/urdf/urdf_generator/8x750roller.stl"/>
</geometry>
<material name="8x750roller_material">
<color rgba="0.792157 0.819608 0.933333 1.0"/>
</material>
</collision>
<inertial>
<origin xyz="0 0 0" rpy="0 0 0"/>
<mass value="0.005"/>
<inertia ixx="0.002" ixy="0"  ixz="0" iyy="0.003" iyz="0" izz="0.003" />
</inertial>
</link>

<joint name="roller_w2_7" type="continuous">
<origin xyz="-0.0517908 0.0767377 -0.0015875" rpy="-2.44346 -1.5708 0" />
<parent link="wheel_3" />
<child link="8x750roller_44" />
<axis xyz="0 0 1"/>
<limit effort="100" velocity="20" />
<joint_properties friction="0.0"/>
</joint>

<link name="8x750roller_45">
<visual>
<origin xyz="8.72708e-09 2.00071e-09 -0.00924558" rpy="1.5708 1.5708 0" />
<geometry>
<mesh filename="package://trikey_description/urdf/urdf_generator/8x750roller.stl"/>
</geometry>
<material name="8x750roller_material">
<color rgba="0.792157 0.819608 0.933333 1.0"/>
</material>
</visual>
<collision>
<origin xyz="8.72708e-09 2.00071e-09 -0.00924558" rpy="1.5708 1.5708 0" />
<geometry>
<mesh filename="package://trikey_description/urdf/urdf_generator/8x750roller.stl"/>
</geometry>
<material name="8x750roller_material">
<color rgba="0.792157 0.819608 0.933333 1.0"/>
</material>
</collision>
<inertial>
<origin xyz="0 0 0" rpy="0 0 0"/>
<mass value="0.005"/>
<inertia ixx="0.002" ixy="0"  ixz="0" iyy="0.003" iyz="0" izz="0.003" />
</inertial>
</link>

<joint name="roller_w2_8" type="continuous">
<origin xyz="-0.0749133 0.0543964 -0.0015875" rpy="1.5708 -9.29494e-17 2.61799" />
<parent link="wheel_3" />
<child link="8x750roller_45" />
<axis xyz="0 0 1"/>
<limit effort="100" velocity="20" />
<joint_properties friction="0.0"/>
</joint>

<link name="8x750roller_46">
<visual>
<origin xyz="8.72708e-09 2.00071e-09 -0.00924558" rpy="1.5708 1.5708 0" />
<geometry>
<mesh filename="package://trikey_description/urdf/urdf_generator/8x750roller.stl"/>
</geometry>
<material name="8x750roller_material">
<color rgba="0.792157 0.819608 0.933333 1.0"/>
</material>
</visual>
<collision>
<origin xyz="8.72708e-09 2.00071e-09 -0.00924558" rpy="1.5708 1.5708 0" />
<geometry>
<mesh filename="package://trikey_description/urdf/urdf_generator/8x750roller.stl"/>
</geometry>
<material name="8x750roller_material">
<color rgba="0.792157 0.819608 0.933333 1.0"/>
</material>
</collision>
<inertial>
<origin xyz="0 0 0" rpy="0 0 0"/>
<mass value="0.005"/>
<inertia ixx="0.002" ixy="0"  ixz="0" iyy="0.003" iyz="0" izz="0.003" />
</inertial>
</link>

<joint name="roller_w2_9" type="continuous">
<origin xyz="-0.0890001 0.025494 -0.0015875" rpy="1.5708 -1.2854e-17 2.96706" />
<parent link="wheel_3" />
<child link="8x750roller_46" />
<axis xyz="0 0 1"/>
<limit effort="100" velocity="20" />
<joint_properties friction="0.0"/>
</joint>

<link name="8x750roller_47">
<visual>
<origin xyz="8.72708e-09 2.00071e-09 -0.00924558" rpy="1.5708 1.5708 0" />
<geometry>
<mesh filename="package://trikey_description/urdf/urdf_generator/8x750roller.stl"/>
</geometry>
<material name="8x750roller_material">
<color rgba="0.792157 0.819608 0.933333 1.0"/>
</material>
</visual>
<collision>
<origin xyz="8.72708e-09 2.00071e-09 -0.00924558" rpy="1.5708 1.5708 0" />
<geometry>
<mesh filename="package://trikey_description/urdf/urdf_generator/8x750roller.stl"/>
</geometry>
<material name="8x750roller_material">
<color rgba="0.792157 0.819608 0.933333 1.0"/>
</material>
</collision>
<inertial>
<origin xyz="0 0 0" rpy="0 0 0"/>
<mass value="0.005"/>
<inertia ixx="0.002" ixy="0"  ixz="0" iyy="0.003" iyz="0" izz="0.003" />
</inertial>
</link>

<joint name="roller_w2_10" type="continuous">
<origin xyz="-0.0923522 -0.00648329 -0.0015875" rpy="1.5708 -5.86296e-17 -2.96706" />
<parent link="wheel_3" />
<child link="8x750roller_47" />
<axis xyz="0 0 1"/>
<limit effort="100" velocity="20" />
<joint_properties friction="0.0"/>
</joint>

<link name="8x750roller_48">
<visual>
<origin xyz="8.72708e-09 2.00071e-09 -0.00924558" rpy="1.5708 1.5708 0" />
<geometry>
<mesh filename="package://trikey_description/urdf/urdf_generator/8x750roller.stl"/>
</geometry>
<material name="8x750roller_material">
<color rgba="0.792157 0.819608 0.933333 1.0"/>
</material>
</visual>
<collision>
<origin xyz="8.72708e-09 2.00071e-09 -0.00924558" rpy="1.5708 1.5708 0" />
<geometry>
<mesh filename="package://trikey_description/urdf/urdf_generator/8x750roller.stl"/>
</geometry>
<material name="8x750roller_material">
<color rgba="0.792157 0.819608 0.933333 1.0"/>
</material>
</collision>
<inertial>
<origin xyz="0 0 0" rpy="0 0 0"/>
<mass value="0.005"/>
<inertia ixx="0.002" ixy="0"  ixz="0" iyy="0.003" iyz="0" izz="0.003" />
</inertial>
</link>

<joint name="roller_w2_11" type="continuous">
<origin xyz="-0.0845653 -0.0376786 -0.0015875" rpy="1.5708 -7.70262e-17 -2.61799" />
<parent link="wheel_3" />
<child link="8x750roller_48" />
<axis xyz="0 0 1"/>
<limit effort="100" velocity="20" />
<joint_properties friction="0.0"/>
</joint>

<link name="8x750roller_49">
<visual>
<origin xyz="8.72708e-09 2.00071e-09 -0.00924558" rpy="1.5708 1.5708 0" />
<geometry>
<mesh filename="package://trikey_description/urdf/urdf_generator/8x750roller.stl"/>
</geometry>
<material name="8x750roller_material">
<color rgba="0.792157 0.819608 0.933333 1.0"/>
</material>
</visual>
<collision>
<origin xyz="8.72708e-09 2.00071e-09 -0.00924558" rpy="1.5708 1.5708 0" />
<geometry>
<mesh filename="package://trikey_description/urdf/urdf_generator/8x750roller.stl"/>
</geometry>
<material name="8x750roller_material">
<color rgba="0.792157 0.819608 0.933333 1.0"/>
</material>
</collision>
<inertial>
<origin xyz="0 0 0" rpy="0 0 0"/>
<mass value="0.005"/>
<inertia ixx="0.002" ixy="0"  ixz="0" iyy="0.003" iyz="0" izz="0.003" />
</inertial>
</link>

<joint name="roller_w2_12" type="continuous">
<origin xyz="-0.0665785 -0.0643294 -0.0015875" rpy="-0.698132 -1.5708 0" />
<parent link="wheel_3" />
<child link="8x750roller_49" />
<axis xyz="0 0 1"/>
<limit effort="100" velocity="20" />
<joint_properties friction="0.0"/>
</joint>

<link name="8x750roller_50">
<visual>
<origin xyz="8.72708e-09 2.00071e-09 -0.00924558" rpy="1.5708 1.5708 0" />
<geometry>
<mesh filename="package://trikey_description/urdf/urdf_generator/8x750roller.stl"/>
</geometry>
<material name="8x750roller_material">
<color rgba="0.792157 0.819608 0.933333 1.0"/>
</material>
</visual>
<collision>
<origin xyz="8.72708e-09 2.00071e-09 -0.00924558" rpy="1.5708 1.5708 0" />
<geometry>
<mesh filename="package://trikey_description/urdf/urdf_generator/8x750roller.stl"/>
</geometry>
<material name="8x750roller_material">
<color rgba="0.792157 0.819608 0.933333 1.0"/>
</material>
</collision>
<inertial>
<origin xyz="0 0 0" rpy="0 0 0"/>
<mass value="0.005"/>
<inertia ixx="0.002" ixy="0"  ixz="0" iyy="0.003" iyz="0" izz="0.003" />
</inertial>
</link>

<joint name="roller_w2_13" type="continuous">
<origin xyz="-0.0405614 -0.083221 -0.0015875" rpy="-0.349066 -1.5708 0" />
<parent link="wheel_3" />
<child link="8x750roller_50" />
<axis xyz="0 0 1"/>
<limit effort="100" velocity="20" />
<joint_properties friction="0.0"/>
</joint>

<link name="8x750roller_51">
<visual>
<origin xyz="-8.72708e-09 -2.00071e-09 -0.00924558" rpy="-1.5708 -1.5708 0" />
<geometry>
<mesh filename="package://trikey_description/urdf/urdf_generator/8x750roller.stl"/>
</geometry>
<material name="8x750roller_material">
<color rgba="0.792157 0.819608 0.933333 1.0"/>
</material>
</visual>
<collision>
<origin xyz="-8.72708e-09 -2.00071e-09 -0.00924558" rpy="-1.5708 -1.5708 0" />
<geometry>
<mesh filename="package://trikey_description/urdf/urdf_generator/8x750roller.stl"/>
</geometry>
<material name="8x750roller_material">
<color rgba="0.792157 0.819608 0.933333 1.0"/>
</material>
</collision>
<inertial>
<origin xyz="0 0 0" rpy="0 0 0"/>
<mass value="0.005"/>
<inertia ixx="0.002" ixy="0"  ixz="0" iyy="0.003" iyz="0" izz="0.003" />
</inertial>
</link>

<joint name="roller_w2_14" type="continuous">
<origin xyz="-0.009652 -0.092075 -0.0015875" rpy="7.41518e-14 -1.5708 0" />
<parent link="wheel_3" />
<child link="8x750roller_51" />
<axis xyz="0 0 1"/>
<limit effort="100" velocity="20" />
<joint_properties friction="0.0"/>
</joint>

<link name="8x750roller_52">
<visual>
<origin xyz="-8.72708e-09 -2.00071e-09 -0.00924558" rpy="-1.5708 -1.5708 0" />
<geometry>
<mesh filename="package://trikey_description/urdf/urdf_generator/8x750roller.stl"/>
</geometry>
<material name="8x750roller_material">
<color rgba="0.792157 0.819608 0.933333 1.0"/>
</material>
</visual>
<collision>
<origin xyz="-8.72708e-09 -2.00071e-09 -0.00924558" rpy="-1.5708 -1.5708 0" />
<geometry>
<mesh filename="package://trikey_description/urdf/urdf_generator/8x750roller.stl"/>
</geometry>
<material name="8x750roller_material">
<color rgba="0.792157 0.819608 0.933333 1.0"/>
</material>
</collision>
<inertial>
<origin xyz="0 0 0" rpy="0 0 0"/>
<mass value="0.005"/>
<inertia ixx="0.002" ixy="0"  ixz="0" iyy="0.003" iyz="0" izz="0.003" />
</inertial>
</link>

<joint name="roller_w2_15" type="continuous">
<origin xyz="0.0224216 -0.0898234 -0.0015875" rpy="0.349066 -1.5708 0" />
<parent link="wheel_3" />
<child link="8x750roller_52" />
<axis xyz="0 0 1"/>
<limit effort="100" velocity="20" />
<joint_properties friction="0.0"/>
</joint>

<link name="8x750roller_53">
<visual>
<origin xyz="-8.72708e-09 -2.00071e-09 -0.00924558" rpy="-1.5708 -1.5708 0" />
<geometry>
<mesh filename="package://trikey_description/urdf/urdf_generator/8x750roller.stl"/>
</geometry>
<material name="8x750roller_material">
<color rgba="0.792157 0.819608 0.933333 1.0"/>
</material>
</visual>
<collision>
<origin xyz="-8.72708e-09 -2.00071e-09 -0.00924558" rpy="-1.5708 -1.5708 0" />
<geometry>
<mesh filename="package://trikey_description/urdf/urdf_generator/8x750roller.stl"/>
</geometry>
<material name="8x750roller_material">
<color rgba="0.792157 0.819608 0.933333 1.0"/>
</material>
</collision>
<inertial>
<origin xyz="0 0 0" rpy="0 0 0"/>
<mass value="0.005"/>
<inertia ixx="0.002" ixy="0"  ixz="0" iyy="0.003" iyz="0" izz="0.003" />
</inertial>
</link>

<joint name="roller_w2_16" type="continuous">
<origin xyz="0.0517908 -0.0767377 -0.0015875" rpy="0.698132 -1.5708 0" />
<parent link="wheel_3" />
<child link="8x750roller_53" />
<axis xyz="0 0 1"/>
<limit effort="100" velocity="20" />
<joint_properties friction="0.0"/>
</joint>

<link name="8x750roller_54">
<visual>
<origin xyz="-8.72708e-09 -2.00071e-09 -0.00924558" rpy="-1.5708 -1.5708 0" />
<geometry>
<mesh filename="package://trikey_description/urdf/urdf_generator/8x750roller.stl"/>
</geometry>
<material name="8x750roller_material">
<color rgba="0.792157 0.819608 0.933333 1.0"/>
</material>
</visual>
<collision>
<origin xyz="-8.72708e-09 -2.00071e-09 -0.00924558" rpy="-1.5708 -1.5708 0" />
<geometry>
<mesh filename="package://trikey_description/urdf/urdf_generator/8x750roller.stl"/>
</geometry>
<material name="8x750roller_material">
<color rgba="0.792157 0.819608 0.933333 1.0"/>
</material>
</collision>
<inertial>
<origin xyz="0 0 0" rpy="0 0 0"/>
<mass value="0.005"/>
<inertia ixx="0.002" ixy="0"  ixz="0" iyy="0.003" iyz="0" izz="0.003" />
</inertial>
</link>

<joint name="roller_w2_17" type="continuous">
<origin xyz="0.0749133 -0.0543964 -0.0015875" rpy="-1.5708 -9.29511e-17 2.61799" />
<parent link="wheel_3" />
<child link="8x750roller_54" />
<axis xyz="0 0 1"/>
<limit effort="100" velocity="20" />
<joint_properties friction="0.0"/>
</joint>

<joint name="wheel2_joint" type="continuous">
<origin xyz="0.227979 0.132092 -0.130855" rpy="-1.5708 -3.25141e-07 -1.04719" />
<parent link="base_link" />
<child link="wheel_3" />
<axis xyz="0 0 1"/>
<limit effort="30" velocity="20" />
<joint_properties friction="0.0"/>
</joint>

    <link name="lidar_mount">
        <visual>
        <origin xyz="0.0 0.0 0.0" rpy="0.0 0.0 0.0" />
        <geometry>
            <box size="0.01 0.01 0.01"/>
        </geometry>
        </visual>
        <inertial>
            <origin xyz="0.0 0.0 0.0" rpy="0.0 0.0 0.0"/>
            <mass value="0.19"/>
            <inertia ixx="0.001" ixy="0.0" ixz="0.0" iyy="0.001" iyz="0.0" izz="0.001"/>
        </inertial>
    </link>

    <joint name="lidar_mount_joint" type="fixed">
        <origin xyz="0.0 -0.23 0.345" rpy="0.0 0.0 0.0"/>
        <parent link="base_link"/>
        <child link="lidar_mount"/>
    </joint>

    <!-- Lidar Link -->
  <link name="rplidar_link">
    <collision>
      <origin xyz="0 0 0" rpy="1.5707 0 1.5707"/>
      <geometry>
	      <mesh filename="package://trikey_description/meshes/rplidar.dae" scale="0.001 0.001 0.001"/>
      </geometry>
    </collision>

    <visual>
      <origin xyz="0 0 0" rpy="1.5705 0 4.71229"/>
      <geometry>
        <mesh filename="package://trikey_description/meshes/rplidar.dae" scale="0.001 0.001 0.001"/>
      </geometry>
    </visual>

    <inertial>
      <mass value="1e-5" />
      <origin xyz="0 0 0" rpy="1.5707 0 1.5707"/>
      <inertia ixx="1e-6" ixy="0" ixz="0" iyy="1e-6" iyz="0" izz="1e-6" />
    </inertial>
  </link>


    <!-- Azure Kinect Camera Link (Top Camera) -->
    <link name="kinect_1_link">
        <visual>
            <origin xyz="0 0 0" rpy="0 0 0"/>
            <geometry>
                <mesh filename="package://trikey_description/meshes/Azure_Kinect.stl"/>
            </geometry>
            <material name="kinect_material">
                <color rgba="0.9 0.2 0.24 1.0"/>
            </material>
        </visual>

        <collision>
            <origin xyz="0.0 0.0 0.0"/>
            <geometry>
                <mesh filename="package://trikey_description/meshes/Azure_Kinect.stl"/>
            </geometry>
            <material name="kinect_material">
                <color rgba="0.9 0.2 0.24 1.0"/>
            </material>
        </collision>

        <inertial>
            <origin xyz="0 0 0" rpy="0 0 0"/>
            <mass value=".44" />
            <inertia ixx="10.173985" ixy="0.212137"  ixz="-0.09591" iyy="5.191632" iyz="0.505713" izz="5.853716" />
        </inertial>
    </link>


    <!-- Azure Kinect Camera Link (Bottom Camera) -->
    <link name="kinect_2_link">
        <visual>
            <origin xyz="0 0 0" rpy="0 0 0"/>
            <geometry>
                <mesh filename="package://trikey_description/meshes/Azure_Kinect.stl"/>
            </geometry>
            <material name="kinect_material">
                <color rgba="0.9 0.2 0.24 1.0"/>
            </material>
        </visual>

        <collision>
            <origin xyz="0.0 0.0 0.0"/>
            <geometry>
                <mesh filename="package://trikey_description/meshes/Azure_Kinect.stl"/>
            </geometry>
            <material name="kinect_material">
                <color rgba="0.9 0.2 0.24 1.0"/>
            </material>
        </collision>

        <inertial>
            <origin xyz="0 0 0" rpy="0 0 0"/>
            <mass value=".44" />
            <inertia ixx="10.173985" ixy="0.212137"  ixz="-0.09591" iyy="5.191632" iyz="0.505713" izz="5.853716" />
        </inertial>
    </link>

  <!-- Azure Kinect Camera Lense Link (Top Camera) -->
  <link name="kinect_1_lense_link">
    <visual>
      <origin xyz="0 0 0" rpy="0 1.57 0" />
      <geometry>
        <cylinder length="0.001" radius="0.01"/>
      </geometry>
    </visual>
  </link>

  <!-- Azure Kinect Camera Lense Link (Bottom Camera) -->
  <link name="kinect_2_lense_link">
    <visual>
      <origin xyz="0 0 0" rpy="0 1.57 0" />
      <geometry>
        <cylinder length="0.001" radius="0.01"/>
      </geometry>
    </visual>
  </link>

<link name="kinect_2_pcl_link">
    <visual>
      <origin xyz="0 0 0" rpy="0 0 0" />
      <geometry>
        <cylinder length="0.001" radius="0.01"/>
      </geometry>
    </visual>
  </link>

    <!-- Kinect Camera Joints -->

    <joint name="kinect_1_joint" type="fixed">
        <origin xyz="-0.01239 -0.289682 0.28607" rpy="0 1.57 -1.57079632679"/>
        <parent link="base_link"/>
        <child link="kinect_1_link"/>
    </joint>

    <joint name="kinect_2_joint" type="fixed">
        <origin xyz="0.01239 -0.289682 0.1734" rpy="0 2.0943951023931953 -1.57079632679"/>
        <parent link="base_link"/>
        <child link="kinect_2_link"/>
    </joint>

    <joint name="kinect_1_lense_joint" type="fixed">
        <origin xyz="-0.03 0 0.01" rpy="3.14 -1.57 0"/>
        <parent link="kinect_1_link"/>
        <child link="kinect_1_lense_link"/>
    </joint>

    <joint name="kinect_2_lense_joint" type="fixed">
        <origin xyz="-0.03 0 0.01" rpy="0 -1.57 0"/>
        <parent link="kinect_2_link"/>
        <child link="kinect_2_lense_link"/>
    </joint>

    <joint name="kinect_2_pcl_joint" type="fixed">
        <origin xyz="0 0 0" rpy="0 0 -1.57079632679"/>
        <parent link="kinect_2_link"/>
        <child link="kinect_2_pcl_link"/>
    </joint>


    <!-- Lidar Joint -->
    <joint name="rplidar_joint" type="fixed">
        <axis xyz="0 1 0" />
        <origin xyz="0 0 0" rpy="0 0 3.14159"/>
        <parent link="lidar_mount"/>
        <child link="rplidar_link"/>
    </joint>

    <!-- RPLidar Sensor -->
    <!-- Noise parameters based on published spec for Hokuyo laser
    achieving "+-30mm" accuracy at range < 10m.  A mean of 0.0m and
    stddev of 0.01m will put 99.7% of samples within 0.03m of the true
    reading. -->
    <!-- specs for RPLidar A2M8
    <gazebo reference="rplidar_link">
        <sensor type="ray" name="rplidar_sensor">
          <pose>0 0 1 0 0 0</pose>
          <visualize>true</visualize>
          <update_rate>10</update_rate>
          <ray>
            <scan>
              <horizontal>
                <samples>400</samples>
                <resolution>1</resolution>
                <min_angle>-3.141593</min_angle>
                <max_angle>3.141593</max_angle>
              </horizontal>
	    </scan>
            <range>
              <min>0.15</min>
              <max>8.0</max>
              <resolution>0.01</resolution>
            </range>
            <noise>
              <type>gaussian</type>
               <mean>0.0</mean>
              <stddev>0.01</stddev>
            </noise>
          </ray>
            <plugin name="gazebo_ros_head_rplidar_controller" filename="libgazebo_ros_laser.so">
            <topicName>/scan</topicName>
            <frameName>rplidar_link</frameName>
        </plugin>
        </sensor>
        <material>Gazebo/Grey</material>
     </gazebo>
     -->

  <!-- Camera Plugin for Gazebo -->
    <!-- Kinect Camera 1 -->
    <gazebo reference="kinect_1_lense_link">
      <sensor type="depth" name="camera1">
        <update_rate>15.0</update_rate>
        <camera name="kinect1">
          <horizontal_fov>2.0944</horizontal_fov>
          <image>
            <width>512</width>
            <height>512</height>
            <format>R8G8B8</format>
          </image>
          <clip>
            <near>0.02</near>
            <far>300</far>
          </clip>
          <noise>
            <type>gaussian</type>
            <!-- Noise is sampled independently per pixel on each frame.
                That pixel's noise value is added to each of its color
                channels, which at that point lie in the range [0,1]. -->
            <mean>0.5</mean>
            <stddev>0.007</stddev>
          </noise>
        </camera>
          <plugin name="kinect_plugin" filename="libgazebo_ros_openni_kinect.so">
                <baseline>0.1</baseline>
                <alwaysOn>true</alwaysOn>
                <!-- Keep this zero, update_rate in the parent <sensor> tag
                will control the frame rate. -->
                <updateRate>0.0</updateRate>
                <cameraName>kinect1</cameraName>
                <robotNamespace>/trikey</robotNamespace>
                <imageTopicName>/kinect1/color/image_raw</imageTopicName>
                <cameraInfoTopicName>/kinect1/camera_info</cameraInfoTopicName>
                <depthImageTopicName>/kinect1/depth/image_raw</depthImageTopicName>
                <depthImageInfoTopicName>/kinect1/depth/camera_info</depthImageInfoTopicName>
                <pointCloudTopicName>/kinect1/points</pointCloudTopicName>
                <frameName>kinect_1_lense_link</frameName>
                <pointCloudCutoff>0.5</pointCloudCutoff>
                <pointCloudCutoffMax>2.0</pointCloudCutoffMax>
            </plugin>
      </sensor>
    </gazebo>

    <!-- Kinect Camera 2 -->
    <gazebo reference="kinect_2_lense_link">
      <sensor type="depth" name="camera2">
        <update_rate>15.0</update_rate>
        <camera name="kinect2">
          <horizontal_fov>2.0944</horizontal_fov>
          <image>
            <width>512</width>
            <height>512</height>
            <format>R8G8B8</format>
          </image>
          <clip>
            <near>0.02</near>
            <far>300</far>
          </clip>
          <noise>
            <type>gaussian</type>
            <!-- Noise is sampled independently per pixel on each frame.
                That pixel's noise value is added to each of its color
                channels, which at that point lie in the range [0,1]. -->
            <mean>0.5</mean>
            <stddev>0.007</stddev>
          </noise>
        </camera>
          <plugin name="kinect_plugin" filename="libgazebo_ros_openni_kinect.so">
                <baseline>0.1</baseline>
                <alwaysOn>true</alwaysOn>
                <!-- Keep this zero, update_rate in the parent <sensor> tag
                will control the frame rate. -->
                <updateRate>0.0</updateRate>
                <cameraName>kinect2</cameraName>
                <robotNamespace>/trikey</robotNamespace>
                <imageTopicName>/kinect2/color/image_raw</imageTopicName>
                <cameraInfoTopicName>/kinect2/camera_info</cameraInfoTopicName>
                <depthImageTopicName>/kinect2/depth/image_raw</depthImageTopicName>
                <depthImageInfoTopicName>/kinect2/depth/camera_info</depthImageInfoTopicName>
                <pointCloudTopicName>/kinect2/points</pointCloudTopicName>
                <frameName>kinect_2_pcl_link</frameName>
                <pointCloudCutoff>0.5</pointCloudCutoff>
                <pointCloudCutoffMax>2.0</pointCloudCutoffMax>
            </plugin>
      </sensor>
    </gazebo>


    <!-- Transmissions: needed for ROS control -->
    <transmission name="wheel0_simple_trans">
        <type>transmission_interface/SimpleTransmission</type>
        <joint name="wheel0_joint">
            <hardwareInterface>hardware_interface/EffortJointInterface</hardwareInterface>
        </joint>
        <actuator name="wheel0_motor">
            <hardwareInterface>hardware_interface/EffortJointInterface</hardwareInterface>
        </actuator>
    </transmission>

    <transmission name="wheel1_simple_trans">
        <type>transmission_interface/SimpleTransmission</type>
        <joint name="wheel1_joint">
            <hardwareInterface>hardware_interface/EffortJointInterface</hardwareInterface>
        </joint>
        <actuator name="wheel1_motor">
            <hardwareInterface>hardware_interface/EffortJointInterface</hardwareInterface>
        </actuator>
    </transmission>

    <transmission name="wheel2_simple_trans">
        <type>transmission_interface/SimpleTransmission</type>
        <joint name="wheel2_joint">
            <hardwareInterface>hardware_interface/EffortJointInterface</hardwareInterface>
        </joint>
        <actuator name="wheel2_motor">
            <hardwareInterface>hardware_interface/EffortJointInterface</hardwareInterface>
        </actuator>
    </transmission>

    <!--==================== Sensors ====================-->



    <!-- Pose Ground Truth -->
    <gazebo>
        <plugin filename="libgazebo_ros_p3d.so" name="gazebo_ros_p3d">
            <robotNamespace>/trikey</robotNamespace>
            <frame_name>odom</frame_name>
            <bodyName>base_link</bodyName>
            <topicName>ground_truth</topicName>
            <frameName>world</frameName>
            <gaussianNoise>0</gaussianNoise>
            <alwaysOn>true</alwaysOn>
            <updateRate>30</updateRate>
        </plugin>
    </gazebo>

    <gazebo>
        <plugin name="gazebo_ros_control" filename="libgazebo_ros_control.so">
            <robotNamespace>/trikey</robotNamespace>
            <controlPeriod>0.001</controlPeriod>
        </plugin>
    </gazebo>




    <!-- Fix jitter -->
    <gazebo reference="8x750roller">
        <mu1>0.8</mu1>
        <mu2>0.8</mu2>
        <kp>50000.0</kp>
        <kd>80.0</kd>
        <minDepth>0.0001</minDepth>
        <maxVel>0</maxVel>
    </gazebo>

    <gazebo reference="8x750roller_2">
        <mu1>0.8</mu1>
        <mu2>0.8</mu2>
        <kp>50000.0</kp>
        <kd>80.0</kd>
        <minDepth>0.0001</minDepth>
        <maxVel>0</maxVel>
    </gazebo>

    <gazebo reference="8x750roller_3">
        <mu1>0.8</mu1>
        <mu2>0.8</mu2>
        <kp>50000.0</kp>
        <kd>80.0</kd>
        <minDepth>0.0001</minDepth>
        <maxVel>0</maxVel>
    </gazebo>

    <gazebo reference="8x750roller_4">
        <mu1>0.8</mu1>
        <mu2>0.8</mu2>
        <kp>50000.0</kp>
        <kd>80.0</kd>
        <minDepth>0.0001</minDepth>
        <maxVel>0</maxVel>
    </gazebo>

    <gazebo reference="8x750roller_5">
        <mu1>0.8</mu1>
        <mu2>0.8</mu2>
        <kp>50000.0</kp>
        <kd>80.0</kd>
        <minDepth>0.0001</minDepth>
        <maxVel>0</maxVel>
    </gazebo>

    <gazebo reference="8x750roller_6">
        <mu1>0.8</mu1>
        <mu2>0.8</mu2>
        <kp>50000.0</kp>
        <kd>80.0</kd>
        <minDepth>0.0001</minDepth>
        <maxVel>0</maxVel>
    </gazebo>

    <gazebo reference="8x750roller_7">
        <mu1>0.8</mu1>
        <mu2>0.8</mu2>
        <kp>50000.0</kp>
        <kd>80.0</kd>
        <minDepth>0.0001</minDepth>
        <maxVel>0</maxVel>
    </gazebo>

    <gazebo reference="8x750roller_8">
        <mu1>0.8</mu1>
        <mu2>0.8</mu2>
        <kp>50000.0</kp>
        <kd>80.0</kd>
        <minDepth>0.0001</minDepth>
        <maxVel>0</maxVel>
    </gazebo>

    <gazebo reference="8x750roller_9">
        <mu1>0.8</mu1>
        <mu2>0.8</mu2>
        <kp>50000.0</kp>
        <kd>80.0</kd>
        <minDepth>0.0001</minDepth>
        <maxVel>0</maxVel>
    </gazebo>

    <gazebo reference="8x750roller_10">
        <mu1>0.8</mu1>
        <mu2>0.8</mu2>
        <kp>50000.0</kp>
        <kd>80.0</kd>
        <minDepth>0.0001</minDepth>
        <maxVel>0</maxVel>
    </gazebo>

    <gazebo reference="8x750roller_11">
        <mu1>0.8</mu1>
        <mu2>0.8</mu2>
        <kp>50000.0</kp>
        <kd>80.0</kd>
        <minDepth>0.0001</minDepth>
        <maxVel>0</maxVel>
    </gazebo>

    <gazebo reference="8x750roller_12">
        <mu1>0.8</mu1>
        <mu2>0.8</mu2>
        <kp>50000.0</kp>
        <kd>80.0</kd>
        <minDepth>0.0001</minDepth>
        <maxVel>0</maxVel>
    </gazebo>

    <gazebo reference="8x750roller_13">
        <mu1>0.8</mu1>
        <mu2>0.8</mu2>
        <kp>50000.0</kp>
        <kd>80.0</kd>
        <minDepth>0.0001</minDepth>
        <maxVel>0</maxVel>
    </gazebo>

    <gazebo reference="8x750roller_14">
        <mu1>0.8</mu1>
        <mu2>0.8</mu2>
        <kp>50000.0</kp>
        <kd>80.0</kd>
        <minDepth>0.0001</minDepth>
        <maxVel>0</maxVel>
    </gazebo>

    <gazebo reference="8x750roller_15">
        <mu1>0.8</mu1>
        <mu2>0.8</mu2>
        <kp>50000.0</kp>
        <kd>80.0</kd>
        <minDepth>0.0001</minDepth>
        <maxVel>0</maxVel>
    </gazebo>

    <gazebo reference="8x750roller_16">
        <mu1>0.8</mu1>
        <mu2>0.8</mu2>
        <kp>50000.0</kp>
        <kd>80.0</kd>
        <minDepth>0.0001</minDepth>
        <maxVel>0</maxVel>
    </gazebo>

    <gazebo reference="8x750roller_17">
        <mu1>0.8</mu1>
        <mu2>0.8</mu2>
        <kp>50000.0</kp>
        <kd>80.0</kd>
        <minDepth>0.0001</minDepth>
        <maxVel>0</maxVel>
    </gazebo>

    <gazebo reference="8x750roller_18">
        <mu1>0.8</mu1>
        <mu2>0.8</mu2>
        <kp>50000.0</kp>
        <kd>80.0</kd>
        <minDepth>0.0001</minDepth>
        <maxVel>0</maxVel>
    </gazebo>

    <gazebo reference="8x750roller_19">
        <mu1>0.8</mu1>
        <mu2>0.8</mu2>
        <kp>50000.0</kp>
        <kd>80.0</kd>
        <minDepth>0.0001</minDepth>
        <maxVel>0</maxVel>
    </gazebo>

    <gazebo reference="8x750roller_20">
        <mu1>0.8</mu1>
        <mu2>0.8</mu2>
        <kp>50000.0</kp>
        <kd>80.0</kd>
        <minDepth>0.0001</minDepth>
        <maxVel>0</maxVel>
    </gazebo>

    <gazebo reference="8x750roller_21">
        <mu1>0.8</mu1>
        <mu2>0.8</mu2>
        <kp>50000.0</kp>
        <kd>80.0</kd>
        <minDepth>0.0001</minDepth>
        <maxVel>0</maxVel>
    </gazebo>

    <gazebo reference="8x750roller_22">
        <mu1>0.8</mu1>
        <mu2>0.8</mu2>
        <kp>50000.0</kp>
        <kd>80.0</kd>
        <minDepth>0.0001</minDepth>
        <maxVel>0</maxVel>
    </gazebo>

    <gazebo reference="8x750roller_23">
        <mu1>0.8</mu1>
        <mu2>0.8</mu2>
        <kp>50000.0</kp>
        <kd>80.0</kd>
        <minDepth>0.0001</minDepth>
        <maxVel>0</maxVel>
    </gazebo>

    <gazebo reference="8x750roller_24">
        <mu1>0.8</mu1>
        <mu2>0.8</mu2>
        <kp>50000.0</kp>
        <kd>80.0</kd>
        <minDepth>0.0001</minDepth>
        <maxVel>0</maxVel>
    </gazebo>

    <gazebo reference="8x750roller_25">
        <mu1>0.8</mu1>
        <mu2>0.8</mu2>
        <kp>50000.0</kp>
        <kd>80.0</kd>
        <minDepth>0.0001</minDepth>
        <maxVel>0</maxVel>
    </gazebo>

    <gazebo reference="8x750roller_26">
        <mu1>0.8</mu1>
        <mu2>0.8</mu2>
        <kp>50000.0</kp>
        <kd>80.0</kd>
        <minDepth>0.0001</minDepth>
        <maxVel>0</maxVel>
    </gazebo>

    <gazebo reference="8x750roller_27">
        <mu1>0.8</mu1>
        <mu2>0.8</mu2>
        <kp>50000.0</kp>
        <kd>80.0</kd>
        <minDepth>0.0001</minDepth>
        <maxVel>0</maxVel>
    </gazebo>

    <gazebo reference="8x750roller_28">
        <mu1>0.8</mu1>
        <mu2>0.8</mu2>
        <kp>50000.0</kp>
        <kd>80.0</kd>
        <minDepth>0.0001</minDepth>
        <maxVel>0</maxVel>
    </gazebo>

    <gazebo reference="8x750roller_29">
        <mu1>0.8</mu1>
        <mu2>0.8</mu2>
        <kp>50000.0</kp>
        <kd>80.0</kd>
        <minDepth>0.0001</minDepth>
        <maxVel>0</maxVel>
    </gazebo>

    <gazebo reference="8x750roller_30">
        <mu1>0.8</mu1>
        <mu2>0.8</mu2>
        <kp>50000.0</kp>
        <kd>80.0</kd>
        <minDepth>0.0001</minDepth>
        <maxVel>0</maxVel>
    </gazebo>

    <gazebo reference="8x750roller_31">
        <mu1>0.8</mu1>
        <mu2>0.8</mu2>
        <kp>50000.0</kp>
        <kd>80.0</kd>
        <minDepth>0.0001</minDepth>
        <maxVel>0</maxVel>
    </gazebo>

    <gazebo reference="8x750roller_32">
        <mu1>0.8</mu1>
        <mu2>0.8</mu2>
        <kp>50000.0</kp>
        <kd>80.0</kd>
        <minDepth>0.0001</minDepth>
        <maxVel>0</maxVel>
    </gazebo>

    <gazebo reference="8x750roller_33">
        <mu1>0.8</mu1>
        <mu2>0.8</mu2>
        <kp>50000.0</kp>
        <kd>80.0</kd>
        <minDepth>0.0001</minDepth>
        <maxVel>0</maxVel>
    </gazebo>

    <gazebo reference="8x750roller_34">
        <mu1>0.8</mu1>
        <mu2>0.8</mu2>
        <kp>50000.0</kp>
        <kd>80.0</kd>
        <minDepth>0.0001</minDepth>
        <maxVel>0</maxVel>
    </gazebo>

    <gazebo reference="8x750roller_35">
        <mu1>0.8</mu1>
        <mu2>0.8</mu2>
        <kp>50000.0</kp>
        <kd>80.0</kd>
        <minDepth>0.0001</minDepth>
        <maxVel>0</maxVel>
    </gazebo>

    <gazebo reference="8x750roller_36">
        <mu1>0.8</mu1>
        <mu2>0.8</mu2>
        <kp>50000.0</kp>
        <kd>80.0</kd>
        <minDepth>0.0001</minDepth>
        <maxVel>0</maxVel>
    </gazebo>

    <gazebo reference="8x750roller_37">
        <mu1>0.8</mu1>
        <mu2>0.8</mu2>
        <kp>50000.0</kp>
        <kd>80.0</kd>
        <minDepth>0.0001</minDepth>
        <maxVel>0</maxVel>
    </gazebo>

    <gazebo reference="8x750roller_38">
        <mu1>0.8</mu1>
        <mu2>0.8</mu2>
        <kp>50000.0</kp>
        <kd>80.0</kd>
        <minDepth>0.0001</minDepth>
        <maxVel>0</maxVel>
    </gazebo>

    <gazebo reference="8x750roller_39">
        <mu1>0.8</mu1>
        <mu2>0.8</mu2>
        <kp>50000.0</kp>
        <kd>80.0</kd>
        <minDepth>0.0001</minDepth>
        <maxVel>0</maxVel>
    </gazebo>

    <gazebo reference="8x750roller_40">
        <mu1>0.8</mu1>
        <mu2>0.8</mu2>
        <kp>50000.0</kp>
        <kd>80.0</kd>
        <minDepth>0.0001</minDepth>
        <maxVel>0</maxVel>
    </gazebo>

    <gazebo reference="8x750roller_41">
        <mu1>0.8</mu1>
        <mu2>0.8</mu2>
        <kp>50000.0</kp>
        <kd>80.0</kd>
        <minDepth>0.0001</minDepth>
        <maxVel>0</maxVel>
    </gazebo>

    <gazebo reference="8x750roller_42">
        <mu1>0.8</mu1>
        <mu2>0.8</mu2>
        <kp>50000.0</kp>
        <kd>80.0</kd>
        <minDepth>0.0001</minDepth>
        <maxVel>0</maxVel>
    </gazebo>

    <gazebo reference="8x750roller_43">
        <mu1>0.8</mu1>
        <mu2>0.8</mu2>
        <kp>50000.0</kp>
        <kd>80.0</kd>
        <minDepth>0.0001</minDepth>
        <maxVel>0</maxVel>
    </gazebo>

    <gazebo reference="8x750roller_44">
        <mu1>0.8</mu1>
        <mu2>0.8</mu2>
        <kp>50000.0</kp>
        <kd>80.0</kd>
        <minDepth>0.0001</minDepth>
        <maxVel>0</maxVel>
    </gazebo>

    <gazebo reference="8x750roller_45">
        <mu1>0.8</mu1>
        <mu2>0.8</mu2>
        <kp>50000.0</kp>
        <kd>80.0</kd>
        <minDepth>0.0001</minDepth>
        <maxVel>0</maxVel>
    </gazebo>

    <gazebo reference="8x750roller_46">
        <mu1>0.8</mu1>
        <mu2>0.8</mu2>
        <kp>50000.0</kp>
        <kd>80.0</kd>
        <minDepth>0.0001</minDepth>
        <maxVel>0</maxVel>
    </gazebo>

    <gazebo reference="8x750roller_47">
        <mu1>0.8</mu1>
        <mu2>0.8</mu2>
        <kp>50000.0</kp>
        <kd>80.0</kd>
        <minDepth>0.0001</minDepth>
        <maxVel>0</maxVel>
    </gazebo>

    <gazebo reference="8x750roller_48">
        <mu1>0.8</mu1>
        <mu2>0.8</mu2>
        <kp>50000.0</kp>
        <kd>80.0</kd>
        <minDepth>0.0001</minDepth>
        <maxVel>0</maxVel>
    </gazebo>

    <gazebo reference="8x750roller_49">
        <mu1>0.8</mu1>
        <mu2>0.8</mu2>
        <kp>50000.0</kp>
        <kd>80.0</kd>
        <minDepth>0.0001</minDepth>
        <maxVel>0</maxVel>
    </gazebo>

    <gazebo reference="8x750roller_50">
        <mu1>0.8</mu1>
        <mu2>0.8</mu2>
        <kp>50000.0</kp>
        <kd>80.0</kd>
        <minDepth>0.0001</minDepth>
        <maxVel>0</maxVel>
    </gazebo>

    <gazebo reference="8x750roller_51">
        <mu1>0.8</mu1>
        <mu2>0.8</mu2>
        <kp>50000.0</kp>
        <kd>80.0</kd>
        <minDepth>0.0001</minDepth>
        <maxVel>0</maxVel>
    </gazebo>

    <gazebo reference="8x750roller_52">
        <mu1>0.8</mu1>
        <mu2>0.8</mu2>
        <kp>50000.0</kp>
        <kd>80.0</kd>
        <minDepth>0.0001</minDepth>
        <maxVel>0</maxVel>
    </gazebo>

    <gazebo reference="8x750roller_53">
        <mu1>0.8</mu1>
        <mu2>0.8</mu2>
        <kp>50000.0</kp>
        <kd>80.0</kd>
        <minDepth>0.0001</minDepth>
        <maxVel>0</maxVel>
    </gazebo>

    <gazebo reference="8x750roller_54">
        <mu1>0.8</mu1>
        <mu2>0.8</mu2>
        <kp>50000.0</kp>
        <kd>80.0</kd>
        <minDepth>0.0001</minDepth>
        <maxVel>0</maxVel>
    </gazebo>
</robot>
